Workbook
Name Check1: Sheet1!$W$231
Name Check2: Sheet1!$W$19
Name Check4: Sheet1!$X$32
Name Check6: Sheet1!$X$38
Name Text10: Sheet1!$W$41
Name Text11: Sheet1!$W$51
Name Text12: Sheet1!$W$69
Name Text13: Sheet1!$W$87
Name Text14: Sheet1!$X$106
Name Text21: Sheet1!$W$120
Name Text24: Sheet1!$W$125
Name Text25: Sheet1!$W$134
Name Text26: Sheet1!$W$142
Name Text27: Sheet1!$W$158
Name Text28: Sheet1!$W$160
Name Text29: Sheet1!$W$162
Name Text30: Sheet1!$W$196
Name Text33: Sheet1!$W$153
Name Text34: Sheet1!$W$17
Name Text35: Sheet1!$W$27
Name Text36: Sheet1!$W$28
Name Text37: Sheet1!$W$42
Name Text38: Sheet1!$W$43
Name Text39: Sheet1!$W$51
Name Text40: Sheet1!$W$52
Name Text41: Sheet1!$W$53
Name Text42: Sheet1!$W$70
Name Text43: Sheet1!$W$71
Name Text45: Sheet1!$W$122
Name Text50: Sheet1!$W$121
Name Text54: Sheet1!$W$14
Name Text55: Sheet1!$W$114
Name Text56: Sheet1!$W$116
Name Text57: Sheet1!$W$1
Name Text58: Sheet1!$W$5
Name Text59: Sheet1!$W$13
Name Text8: Sheet1!$W$27
Name Text9: Sheet1!$W$40

Sheet Sheet1
A1: wardlast | B1: wardfirst | C1: wardmiddle | D1: causeno | E1: visitdate | F1: visittime | G1: wtele | H1: liveswith | I1: waddress | J1: wdob | K1: guardian1 | L1: gaddress | M1: gemail | N1: gtele | O1: Relationship | P1: gdob | Q1: Guardian2 | R1: g2 address | S1: g2eamil | T1: g2tele | U1: g2Relationship | V1: g2dob | W1: datesubmitted | X1: Dateappointed | Y1: miles | Z1: expensesubmitted | AA1: expensepd | AB1: Date ARP filed | AC1: Comments | AD1: CVR created?
A2: Wagner | B2: John Carter | D2: 21-001411 | E2: 45883 | F2: 0.47916667 | G2: 512-514-4444 | H2: parents | I2: 412 Cargill Dr., Spicewood, TX 78699 | J2: 37842 | K2: Wagner, Todd and Sara | L2: 412 Cargill Dr., Spicewood, TX 78699 | M2: txgirl14boys@gmail.com | N2: 320-808-9453 | O2: Father/Mother | P2: 9/28/1973 5/01/1976 | W2: 45883 | X2: 45875 | AD2: Y
A3: Dennis | B3: Abigail | D3: 17-000729 | E3: 45883 | F3: 0.65625 | G3: 512-202-9638 | H3: parents | I3: 11508 Shoreview Overlook, Austin, TX | J3: 36252 | K3: Joe and Lisa Dennis | L3: 11508 Shoreview Overlook, Austin, TX 78732 | M3: ljdenis214@gmail.com | N3: 512-808-8823 512-808-8821 | O3: Father/Mother | P3: 7/5/1971 2/14/1972 | W3: 45885 | X3: 45875 | AD3: Y
A4: Halford | B4: Jon Tyler | D4: 22-001301 | E4: 45877 | F4: 0.64583333 | G4: 612-387-1813 | H4: parents | I4: 1700 Amis Ave, Austin, TX 78734 | J4: 38373 | K4: Halford, Jonnie and Amy | L4: 1700 Amis Ave, Austin, TX 78734 | M4: amyhalford710@gmail.com | N4: 612-387-1813 | O4: Father/Mother | P4: 12/17/1976 9/30/1976 | Q4: Lives in gated community, apppears happy nd says he is happy. Active in sports, work and walks dog. | W4: 45877 | X4: 45875 | AD4: Y
A5: Braden | B5: Daniel | D5: 22-002249 | E5: 45882 | F5: 0.5 | H5: nursing home | I5: Barton Valley Rehab & HC 4501 Dudmar Dr., Austin, TX 78735 | J5: 1/03/1959q | K5: Mir Senior Care & Care Consultants | L5: 3410 Far West Blvd, Suite 120, Austin TX | M5: lina@mircareconsultants.com | O5: Professional Guardian | Q5: Kristin Martinelli,was case manager for long time 512.694.7448 Now Emmy Ledbetter 512.234.5515 | W5: 45882 | X5: 45875 | AD5: Y
A6: Conner | B6: Julian Mayerik | D6: 16-000206 | E6: 45882 | F6: 0.60416667 | G6: 503-853-2788 | H6: parents | I6: 4509 Tambre Bnd, Austin, TX 78738 | J6: 9/9//98 | K6: Val Mayerick Tatiana Mayerik | L6: 4509 Tambre Bnd, Austin, TX 78738 | M6: valmayerik@gmail.com | N6: 971-506-8665 503-853-2788 | O6: Father/Mother | P6: 3/29/1950 8/20/1960 | W6: 45883 | X6: 45876 | AD6: Y
A7: De Jong | B7: Brendan James | D7: 14-002049 | E7: 45892 | F7: 0.625 | H7: mother | I7: 15905 Chateau Ave, Austin, TX | J7: 35791 | K7: Kimberly Ellison De Jong | L7: 15905 Chateau Ave, Austin, Texas 78734 | M7: kedejong@msn.com | N7: 240-418-2233 | O7: Mother | P7: 22374 | W7: 45892 | X7: 45881 | AD7: Y
A8: Eudy | B8: Kimberly Grace | D8: 06-084450 | E8: 45884 | F8: 0.54166667 | G8: 512-925-9215 | H8: apartment | I8: Avanti Hills at the Galleria 12601 Bee Cave Parkway, Apt 2-225 BeeCave, TX 78738 | J8: 32230 | K8: Eudy Kimberly H | L8: 121 Lido street, Austin, TX 78734 | M8: braden ca | N8: 512-940-2545 | O8: Mother | P8: 20776 | W8: 45886 | X8: 45881 | AD8: Y
A9: Jones | B9: Andrew Colton | D9: 20-001710 | E9: 45884 | F9: 0.58333333 | G9: 512-565-3313 | H9: apartment | I9: Avanti Hills at the Galleria 12601 Bee Cave Parkway, Apt 243 Bee Cave TX 78738 | J9: 37542 | K9: Jones, Andrew P. | L9: 303 Bellagio Dr, Austin, TX 78734 | M9: apjon1@yahoo.com | N9: 832-3167953 | O9: Father | P9: 24153 | W9: 45886 | X9: 45881 | AD9: Y
A10: Park | B10: Mina | D10: 18-001798 | E10: 45884 | F10: 0.5 | G10: 512-815-8640 | H10: assisted living | I10: 107 Bella Montagna Circle, Lakeway, TX | J10: 10861 | K10: Park, Randal Michael | L10: 1306 Fernglade Lane, Cedar Park, TX 78613 | M10: randalpark@yahoo.com | N10: 512-848-3024 | O10: Son | P10: 21307 | W10: 45886 | X10: 45881 | AC10: Lives in Belmont Village AL, 95 yr old potential need to move to memory care | AD10: Y
A11: Bennett | B11: Luke Thomas | D11: 19-000060 | E11: 45884 | F11: 0.41666667 | G11: 512-762-5949 | H11: parents | I11: 4300 Hennig Dr, Austin, TX 78738 | J11: 36929 | K11: Thomas, Brad and Courtney | L11: 4300 Hennig Drive, Austin, TX 78738 | M11: courtneythomasou91@gmail.com | N11: 512-762-5949 | O11: Father/Mother | P11: 7/28/1969 10/13/1968 | W11: 45885 | X11: 45881 | AD11: Y
A12: Davidson | B12: Anthony Michael | D12: 15-002046 | E12: 45896 | F12: 0.5 | G12: 512-826-1260 | H12: parents | I12: 6008 Gunnison Turn Rd, Austin, TX 78738 | J12: 35729 | K12: Davidson, Marcela | L12: 6008 Gunnison Turn Rd, Austin, TX 78738 | M12: mdavidson7@austin.rr.com | N12: 512-317-4727 | O12: Mother | P12: 24110 | Q12: marcydavidson531@gmail.com | W12: 45896 | X12: 45888 | AD12: Y
A13: Dodson | B13: Michael Todd | D13: 12-000189 | G13: 512-435-7969 | H13: Mother | I13: 900 Elder Circle, Austin, TX 78733 | J13: 34415 | K13: Mooring, Elisa Berkman | L13: 900 Elder Circle, Austin, TX 78733 | M13: lismooring@aol.com | N13: 512-435-7969 | O13: Mother | P13: 23235 | Q13: Davidson, Daniel | R13: 6009 Gunnison Turn Rd, Austin, TX 78738 | S13: danieldavidson879@gmail.com | T13: 512-826-1260 | U13: Father | V13: 23893 | X13: 45888 | AC13: Cannot schedule until October at horseback riding camp | AD13: Y
A14: Hall | B14: Alexandra | D14: 08-088136 | E14: 45896 | F14: 0.625 | H14: parents | I14: 2 Prestonwood Circle, Lakeway, TX 78737 | J14: 32931 | K14: Hall Kari | L14: 2 Prestonwood Circle, Lakewy, TX 78737 | N14: 512-560-4256 | O14: Mother | P14: 22119 | Q14: Hall, Derek | R14: 3 Prestonwood Circle, Lakewy, TX 78737 | U14: Father | V14: 20537 | W14: 45896 | X14: 45888 | AD14: Y
A15: Jain | B15: Ryan | D15: 24-001242 | E15: 45896 | F15: 0.58333333 | H15: parents | I15: 105 Bel Lago Cove, Austin, TX 78734 | J15: 38911 | K15: Jain Meenu | L15: 105 Bel Lago Cove, Austin, TX 78734 | M15: meenu.jain@gmail.com | N15: 512-786-3084 | O15: Father | P15: 27696 | Q15: Jain, Ankur | R15: 105 Bel Lago Cove, Austin, TX 78734 | S15: ankur.ankurjain@gmail.com | T15: 512-743-1849 | U15: Mother | V15: 27465 | W15: 45896 | X15: 45888 | AD15: Y
A16: Loy | B16: Mary K. | D16: 09-000016 | E16: 45897 | F16: 0.5625 | G16: 512-743-7711 | H16: parents | I16: 208 Darwins Way, Lakeway, TX, 78734 | J16: 20884 | K16: Loy, Charles E. | L16: 208 Darwins Way, Lakeway, TX, 78734 | M16: melyssaloy@mac.com | N16: 512-743-1845 | O16: Father | P16: 21311 | Q16: Loy, Melyssa | R16: 209 Darwins Way, Lakeway, TX, 78734 | U16: Mother | W16: 45897 | X16: 45888 | AD16: Y
A17: Taylor | B17: Ryan Matthew | D17: 22-000706 | E17: 45896 | F17: 0.66666667 | G17: 512-791-7251 | H17: parents | I17: 6416 Llano Stage Trl, Austin, TX 78738 | J17: 38124 | K17: Taylor Brian | L17: 6416 Llano Stage Trl, Austin, TX 78738 | N17: 512-415-7754 | O17: Father | P17: 24820 | Q17: Taylor, Nicole | R17: 6416 Llano Stage Trl, Austin, TX 78738 | S17: nktaylor76@gmail.com | T17: 512-791-7251 | U17: Mother | V17: 27982 | W17: 45896 | X17: 45888 | AD17: Y
A18: Turnbaugh | B18: Elizabeth | D18: 00-074302 | E18: 45896 | F18: 0.70833333 | H18: parents | I18: 22 Hedgebrook Way, Austin, TX 78738 | J18: 31904 | K18: Turnbaugh, Jill | L18: 22 Hedgebrook Way, Austin, TX 78738 | O18: Mother | P18: 19757 | Q18: Turnbaugh, Dean | R18: 22 Hedgebrook Way, Austin, TX 78738 | U18: Father | V18: 20048 | W18: 45896 | X18: 45888 | AD18: Y
A19: Warren | B19: David Patrick | D19: 23-000357 | E19: 45897 | F19: 0.60416667 | H19: parents | I19: 13213 Country Lake Drive, Austin, TX 78732 | J19: 38390 | K19: Warren, Phillip Bowman | L19: 13213 Country Lake Drive, Austin, TX 78732 | N19: 512-963-6504 | O19: Father | P19: 22227 | Q19: Warren, Julie Powell | R19: 13213 Country Lake Drive, Austin, TX 78732 | S19: juliepowellwarren@gmail.com | T19: 512-461-3015 | U19: Mother | V19: 23237 | W19: 45897 | X19: 45888 | AD19: Y
A20: Luna | B20: Oscar | D20: 05-82942 | E20: 45903 | F20: 0.625 | H20: Mother | I20: 2406 Monarch Dr, Austin, TX 78748 | J20: 31916 | K20: Medel, Catalina | L20: 2406 Monarch Dr, Austin, TX 78748 | M20: medelc64@gmail.com | N20: 512-282-1208 | O20: Mother | P20: 23486 | W20: 45904 | X20: t | AD20: Y
A21: Brener | B21: Benjamin | D21: 06-085777 | E21: 45905 | F21: 0.66666667 | I21: 2404 Roe hampton Dr., Austin, TX 78745 | J21: 32518 | K21: Brener, Fay | L21: 4040 Enclave Mesa Circle, Austin, TX 78731 | M21: brefaye@hotmail.com | N21: 512-338-0176 | O21: Mother | P21: 20843 | Q21: Brener, Lazaro | R21: 4040 Enclave Mesa Circle, Austin, TX 78731 | S21: lazarbre@hotmail.com | U21: father | V21: 17061 | W21: 45908 | X21: 45896 | AB21: 45727 | AD21: Y
A22: Potter | B22: Mark | D22: 09-001594 | E22: 45905 | F22: 0.70833333 | G22: 512-789-4079 | H22: Mark I Residential Services Group Home | I22: 2517 McGregor Lane, Austin, TX 78745 | J22: 20160 | K22: Family Eldercare, Inc. Chrisi Johnson, Care Manager | L22: 1700 Rutherford Ln, Austin, TX 78754 | M22: cjohnson@familyeldercare.org | N22: 512-628-1693 | W22: 45908 | X22: 45897 | AB22: 45747 | AD22: Y
A23: Reich | B23: Quinn | D23: 14-000172 | E23: 45908 | F23: 0.60416667 | G23: 512-517-5680 | H23: own home | I23: 6008 Rutledge Ln, Austin, TX 78745 | J23: 35094 | K23: LeBoeuf | L23: 5120 Concho Creek Bend, Austin, TX 78735 | M23: lleboeuf0807@gmail.com | N23: 512-517-5680 | O23: parent | P23: 22865 | Q23: Reich, Stephanie | R23: 205 Laurelwood Trail, Austin, TX 78746 | T23: 512-306-7314 | V23: 22712 | W23: 45908 | X23: 45897 | AB23: 45821 | AD23: Y
A24: Cox | B24: Ty | D24: 15-000428 | E24: 45904 | F24: 0.66666667 | G24: 512-698-0502 | H24: mother and father | I24: 4415 Huffman Drive, Austin, TX 78749 | J24: 33381 | K24: Cox, Matthew | L24: 4415 Hoffman Drive, Austin, TX 78749 | M24: mattjoncox@gmail.com | N24: 512-698-0502 | O24: father | P24: 23892 | Q24: Cox, Amy | R24: 4415 Hoffman Dr., Austin, TX 78749 | S24: amykcox1964@gmail.com | U24: mother | V24: 23613 | W24: 45904 | X24: 45897 | AB24: 45810 | AD24: Y
A25: Roberts | B25: Jay | D25: 17-000201 | E25: 45904 | F25: 0.54166667 | G25: 512-560-2265 | H25: father/mother | I25: 6452 Ruxton Ln, Austin, TX 78749 | J25: 36216 | K25: Roberts, Jay | L25: 6452 Ruxton Ln, Austin, TX 78749 | M25: streboryaj@gmail.com | N25: 512-417-2350 | O25: father | P25: 24667 | Q25: Roberts, Ellen | R25: 6452 Ruxton Ln, Austin, TX 78749 | S25: strebornelle@gmail.com | T25: 512-560-2265 | U25: mother | V25: 26443 | W25: 45904 | X25: 45896 | AB25: 45726 | AD25: Y
A26: Toney | B26: Emma | D26: 18-000194 | E26: 45903 | F26: 0.70833333 | G26: 512-585-8505 | H26: father/mother | I26: 570 Woodland Dr., Driftwood, TX 78619 | J26: 35690 | K26: Toney, Derrick | L26: 570 Woodland Dr., Driftwood, TX 78619 | M26: datoney2@gmail.com | N26: 512-585-8505 | O26: father | P26: 23758 | Q26: Toney, Sara Jane | R26: 570 Woodland Dr., Driftwood, TX 78619 | W26: 45904 | X26: 45897 | AB26: 45684 | AD26: Y
A27: Huerta | B27: Gabriela | D27: 19-002069 | E27: 45904 | F27: 0.77083333 | G27: 512-497-3944 | H27: father/mother | I27: 8800 Ravello Pass, Austin, TX 78749 | J27: 37074 | K27: Huerta, Julian | L27: 6207 Old Harbor, Austin, TX 78739 | N27: 512-826-1616 | O27: father | P27: 23998 | Q27: Huerta Isabel | R27: 8800 Ravello Pass, Austin, TX 78749 | S27: i.huerta@sammyshouse.com | T27: 512-497-3944 | U27: mother | V27: 21954 | W27: 45908 | X27: 45896 | AB27: 45744 | AD27: Y
A28: Ximenez | B28: Jose | D28: 99-071988 | E28: 45905 | F28: 0.72916667 | G28: 512-448-9559 | H28: Mark I Residential Services Group Home | I28: 2517 McGregor Dr., Austin, TX 78745 | J28: 29809 | K28: Family Eldercare Robert Lontkowski, Care Manager | L28: 1700 Rutherford Ln, Austin, TX 78754 | M28: rlontkowski@familyeldercare.org | N28: 512-483-3564 | O28: Public Guardian | W28: 45908 | X28: 45897 | AB28: 45740 | AC28: case manager is Mark Henson mrk1res@swbell.net Jeanette is staff after 4 pm | AD28: Y
A29: Wolk | B29: James | C29: David | D29: 05-082943 | G29: (512) 914-5464 | H29: Guardian | I29: 101 AcapulcoCourt, Austin. TX 78734 | J29: 01/23/1987 | K29: If Co-guardians | L29: 101AcapulcoCourt, Austin. TX 78734 | M29: magda.wolk@gmail.com | N29: (512) 914-5464 | O29: : Mom | P29: 08/07/1951 | Q29: None | X29: 09/16/2025 | AB29: 07/22/2025 | AC29: 2025-10-02 10:41:56
A30: Jimmerson | B30: Abby | C30: Marie | D30: 13-000934 | G30: (512) 923-6754 | H30: parents | I30: 3204 Oksheer Dr., Austin, TX 78732 | J30: 06/09/1995 | K30: Gwendelynn Jimmerson | L30: 3204 Oksheer Dr., Austin, TX 78732 | M30: wendyjimmerson@gmail.com | N30: 512-923-6754 | O30: Mom | P30: 24139 | Q30: James Jimmerson | R30: 3204 Oksheer Dr., Austin, TX 78732 | T30: 512-914-0943 | U30: Father | V30: 23096 | X30: 09/16/2025 | AB30: 07/21/2025 | AC30: 2025-10-02 10:41:58
A31: Cagle | B31: Sara | C31: Elliott | D31: 19-000694 | G31: (713) 380-7865 | H31: parents | I31: 9303 Scenic Bluff Dr., Austin, Texas 78733 | J31: 06/21/2001 | K31: Thomas Patrick Cagle | L31: 9303 Scenic Bluff Dr., Austin, Texas 78733 | M31: tpcaglejr@gmail.com | N31: (713) 380-7865 | O31: Father | P31: 08/16/1965 | Q31: Nicole Cagle | R31: 9303 Scenic Bluff Dr., Austin, Texas 78733 | S31: none | T31: none | U31: Mother | V31: 04/15/1965 | X31: 09/16/2025 | AB31: 45859 | AC31: 2025-10-02 10:41:59
A32: Mogonye | B32: Mason | C32: Todd | D32: 21-000066 | G32: (737) 230-6831 | H32: parents | I32: 12834 Texas Sage Court, Austin, TX | J32: 03/14/2003 | K32: Michael Mogonye | L32: 12834 Texas Sage Court, Austin, TX | M32: JeM0801@gmail.com | N32: (512) 694-6202 | O32: Father | P32: 28077 | Q32: Joslyne Mogonye | R32: 12834 Texas Sage Court, Austin, TX | S32: none | T32: (512) 771-1695 | U32: Mother | V32: 26735 | X32: 45916 | AB32: 45834 | AC32: 2025-10-02 10:41:17
A33: Zarola | B33: Aidan | C33: Jack | D33: 22-002744 | G33: (619) 316-2897 | H33: parents | I33: 104 Largo Cove, Austin/TX/78734 | J33: 08/20/2000 | K33: Michael Zarola | L33: 104 Largo Cove, Austin/TX/78734 | M33: thezarolas@gmail.com | N33: (619) 316-2897 | O33: Father | P33: 26596 | Q33: Veronica Zarola | R33: 104 Largo Cove, Austin/TX/78734 | S33: none | T33: none | U33: Mother | V33: 25830 | X33: 09/16/2025 | AB33: 45869 | AC33: 2025-10-02 10:42:02

Sheet Sheet2
A1: causeno | B1: dateappointed | C1: visitdate | D1: datesubmitted | G1: directions | I1: name
A2: =Sheet1!D2 -> 21-001411 | B2: =Sheet1!X2 -> 45875 | C2: =Sheet1!E2 -> 45883 | D2: =Sheet1!W2 -> 45883 | G2: =HYPERLINK("https://www.google.com/maps/dir//''/data=!4m7?q="&J2,"Get Directions") -> Get Directions | I2: =Sheet1!A2 -> Wagner | J2: =Sheet1!B2 -> John Carter
A3: =Sheet1!D3 -> 17-000729 | B3: =Sheet1!X3 -> 45875 | C3: =Sheet1!E3 -> 45883 | D3: =Sheet1!W3 -> 45885 | G3: =HYPERLINK("https://www.google.com/maps/dir/Current+Location/"&J3,"Get Directions") -> Get Directions | I3: =Sheet1!A3 -> Dennis | J3: =Sheet1!B3 -> Abigail
A4: =Sheet1!D4 -> 22-001301 | B4: =Sheet1!X4 -> 45875 | C4: =Sheet1!E4 -> 45877 | D4: =Sheet1!W4 -> 45877 | G4: =HYPERLINK("https://www.google.com/maps/dir/Current+Location/"&J4,"Get Directions") -> Get Directions | I4: =Sheet1!A4 -> Halford | J4: =Sheet1!B4 -> Jon Tyler
A5: =Sheet1!D5 -> 22-002249 | B5: =Sheet1!X5 -> 45875 | C5: =Sheet1!E5 -> 45882 | D5: =Sheet1!W5 -> 45882 | G5: =HYPERLINK("https://www.google.com/maps/dir/Current+Location/"&J5,"Get Directions") -> Get Directions | I5: =Sheet1!A5 -> Braden | J5: =Sheet1!B5 -> Daniel
A6: =Sheet1!D6 -> 16-000206 | B6: =Sheet1!X6 -> 45876 | C6: =Sheet1!E6 -> 45882 | D6: =Sheet1!W6 -> 45883 | G6: =HYPERLINK("https://www.google.com/maps/dir/Current+Location/"&J6,"Get Directions") -> Get Directions | I6: =Sheet1!A6 -> Conner | J6: =Sheet1!B6 -> Julian Mayerik
A7: =Sheet1!D7 -> 14-002049 | B7: =Sheet1!X7 -> 45881 | C7: =Sheet1!E7 -> 45892 | D7: =Sheet1!W7 -> 45892 | G7: =HYPERLINK("https://www.google.com/maps/dir/Current+Location/"&J7,"Get Directions") -> Get Directions | I7: =Sheet1!A7 -> De Jong | J7: =Sheet1!B7 -> Brendan James
A8: =Sheet1!D8 -> 06-084450 | B8: =Sheet1!X8 -> 45881 | C8: =Sheet1!E8 -> 45884 | D8: =Sheet1!W8 -> 45886 | G8: =HYPERLINK("https://www.google.com/maps/dir/Current+Location/"&J8,"Get Directions") -> Get Directions | I8: =Sheet1!A8 -> Eudy | J8: =Sheet1!B8 -> Kimberly Grace
A9: =Sheet1!D9 -> 20-001710 | B9: =Sheet1!X9 -> 45881 | C9: =Sheet1!E9 -> 45884 | D9: =Sheet1!W9 -> 45886 | G9: =HYPERLINK("https://www.google.com/maps/dir/Current+Location/"&J9,"Get Directions") -> Get Directions | I9: =Sheet1!A9 -> Jones | J9: =Sheet1!B9 -> Andrew Colton
A10: =Sheet1!D10 -> 18-001798 | B10: =Sheet1!X10 -> 45881 | C10: =Sheet1!E10 -> 45884 | D10: =Sheet1!W10 -> 45886 | G10: =HYPERLINK("https://www.google.com/maps/dir/Current+Location/"&J10,"Get Directions") -> Get Directions | I10: =Sheet1!A10 -> Park | J10: =Sheet1!B10 -> Mina
A11: =Sheet1!D11 -> 19-000060 | B11: =Sheet1!X11 -> 45881 | C11: =Sheet1!E11 -> 45884 | D11: =Sheet1!W11 -> 45885 | G11: =HYPERLINK("https://www.google.com/maps/dir/Current+Location/"&J11,"Get Directions") -> Get Directions | I11: =Sheet1!A11 -> Bennett | J11: =Sheet1!B11 -> Luke Thomas
A12: =Sheet1!D12 -> 15-002046 | B12: =Sheet1!X12 -> 45888 | C12: =Sheet1!E12 -> 45896 | D12: =Sheet1!W12 -> 45896 | G12: =HYPERLINK("https://www.google.com/maps/dir/Current+Location/"&J12,"Get Directions") -> Get Directions | I12: =Sheet1!A12 -> Davidson | J12: =Sheet1!B12 -> Anthony Michael
A13: =Sheet1!D13 -> 12-000189 | B13: =Sheet1!X13 -> 45888 | C13: =Sheet1!E13 -> 0 | D13: =Sheet1!W13 -> 0 | G13: =HYPERLINK("https://www.google.com/maps/dir/Current+Location/"&J13,"Get Directions") -> Get Directions | I13: =Sheet1!A13 -> Dodson | J13: =Sheet1!B13 -> Michael Todd
A14: =Sheet1!D14 -> 08-088136 | B14: =Sheet1!X14 -> 45888 | C14: =Sheet1!E14 -> 45896 | D14: =Sheet1!W14 -> 45896 | G14: =HYPERLINK("https://www.google.com/maps/dir/Current+Location/"&J14,"Get Directions") -> Get Directions | I14: =Sheet1!A14 -> Hall | J14: =Sheet1!B14 -> Alexandra
A15: =Sheet1!D15 -> 24-001242 | B15: =Sheet1!X15 -> 45888 | C15: =Sheet1!E15 -> 45896 | D15: =Sheet1!W15 -> 45896 | G15: =HYPERLINK("https://www.google.com/maps/dir/Current+Location/"&J15,"Get Directions") -> Get Directions | I15: =Sheet1!A15 -> Jain | J15: =Sheet1!B15 -> Ryan
A16: =Sheet1!D16 -> 09-000016 | B16: =Sheet1!X16 -> 45888 | C16: =Sheet1!E16 -> 45897 | D16: 45897 | G16: =HYPERLINK("https://www.google.com/maps/dir/Current+Location/"&J16,"Get Directions") -> Get Directions | I16: =Sheet1!A16 -> Loy | J16: =Sheet1!B16 -> Mary K.
A17: =Sheet1!D17 -> 22-000706 | B17: =Sheet1!X17 -> 45888 | C17: =Sheet1!E17 -> 45896 | D17: =Sheet1!W17 -> 45896 | G17: =HYPERLINK("https://www.google.com/maps/dir/Current+Location/"&J17,"Get Directions") -> Get Directions | I17: =Sheet1!A17 -> Taylor | J17: =Sheet1!B17 -> Ryan Matthew
A18: =Sheet1!D18 -> 00-074302 | B18: =Sheet1!X18 -> 45888 | C18: =Sheet1!E18 -> 45896 | D18: =Sheet1!W18 -> 45896 | G18: =HYPERLINK("https://www.google.com/maps/dir/Current+Location/"&I18,"Get Directions") -> Get Directions | I18: =Sheet1!A18 -> Turnbaugh | J18: =Sheet1!B18 -> Elizabeth
A19: =Sheet1!D19 -> 23-000357 | B19: =Sheet1!X19 -> 45888 | C19: =Sheet1!E19 -> 45897 | D19: 45897 | G19: =HYPERLINK("https://www.google.com/maps/dir/Current+Location/"&J19,"Get Directions") -> Get Directions | I19: =Sheet1!A19 -> Warren | J19: =Sheet1!B19 -> David Patrick
A20: =Sheet1!D21 -> 06-085777 | B20: =Sheet1!X20 -> t | C20: =Sheet1!E20 -> 45903 | D20: =Sheet1!W20 -> 45904 | G20: =HYPERLINK("https://www.google.com/maps/dir/Current+Location/"&J20,"Get Directions") -> Get Directions | I20: =Sheet1!A20 -> Luna | J20: =Sheet1!B20 -> Oscar | L20: Luna
A21: =Sheet1!D22 -> 09-001594 | B21: =Sheet1!X21 -> 45896 | C21: =Sheet1!E21 -> 45905 | D21: =Sheet1!W21 -> 45908 | I21: =Sheet1!A21 -> Brener | J21: =Sheet1!B21 -> Benjamin | L21: Brener
A22: =Sheet1!D22 -> 09-001594 | B22: =Sheet1!X22 -> 45897 | C22: =Sheet1!E22 -> 45905 | D22: =Sheet1!W22 -> 45908 | G22: =HYPERLINK("https://www.google.com/maps/dir/Current+Location/"&J22,"Get Directions") -> Get Directions | I22: =Sheet1!A22 -> Potter | J22: =Sheet1!B22 -> Mark | L22: Potter
A23: =Sheet1!D23 -> 14-000172 | B23: =Sheet1!X23 -> 45897 | C23: =Sheet1!E23 -> 45908 | D23: =Sheet1!W23 -> 45908 | G23: =HYPERLINK("https://www.google.com/maps/dir/Current+Location/"&J23,"Get Directions") -> Get Directions | I23: =Sheet1!A23 -> Reich | J23: =Sheet1!B23 -> Quinn | L23: Reich
A24: =Sheet1!D24 -> 15-000428 | B24: =Sheet1!X24 -> 45897 | C24: =Sheet1!E24 -> 45904 | D24: =Sheet1!W24 -> 45904 | G24: =HYPERLINK("https://www.google.com/maps/dir/Current+Location/"&J24,"Get Directions") -> Get Directions | I24: =Sheet1!A24 -> Cox | J24: =Sheet1!B24 -> Ty | L24: Cox
A25: =Sheet1!D25 -> 17-000201 | B25: =Sheet1!X25 -> 45896 | C25: =Sheet1!E25 -> 45904 | D25: =Sheet1!W25 -> 45904 | G25: =HYPERLINK("https://www.google.com/maps/dir/Current+Location/"&J25,"Get Directions") -> Get Directions | I25: =Sheet1!A25 -> Roberts | J25: =Sheet1!B25 -> Jay | L25: Roberts
A26: =Sheet1!D26 -> 18-000194 | B26: =Sheet1!X26 -> 45897 | C26: =Sheet1!E26 -> 45903 | D26: =Sheet1!W26 -> 45904 | G26: =HYPERLINK("https://www.google.com/maps/dir/Current+Location/"&J26,"Get Directions") -> Get Directions | I26: =Sheet1!A26 -> Toney | J26: =Sheet1!B26 -> Emma | L26: Toney
A27: =Sheet1!D27 -> 19-002069 | B27: =Sheet1!X27 -> 45896 | C27: =Sheet1!E27 -> 45904 | D27: =Sheet1!W27 -> 45908 | G27: =HYPERLINK("https://www.google.com/maps/dir/Current+Location/"&J27,"Get Directions") -> Get Directions | I27: =Sheet1!A27 -> Huerta | J27: =Sheet1!B27 -> Gabriela | L27: Huerta
A28: =Sheet1!D28 -> 99-071988 | B28: =Sheet1!X28 -> 45897 | C28: =Sheet1!E28 -> 45905 | D28: =Sheet1!W28 -> 45908 | G28: =HYPERLINK("https://www.google.com/maps/dir/Current+Location/"&J28,"Get Directions") -> Get Directions | I28: =Sheet1!A28 -> Ximenez | J28: =Sheet1!B28 -> Jose | L28: Ximenez
A29: =Sheet1!D29 -> 05-082943 | B29: =Sheet1!X29 -> 09/16/2025 | C29: =Sheet1!E29 -> 0 | D29: =Sheet1!W29 -> 0 | G29: =HYPERLINK("https://www.google.com/maps/dir/Current+Location/"&J29,"Get Directions") -> Get Directions | I29: =Sheet1!A29 -> Wolk | J29: =Sheet1!B29 -> James
A30: =Sheet1!D30 -> 13-000934 | B30: =Sheet1!X30 -> 09/16/2025 | C30: =Sheet1!E30 -> 0 | D30: =Sheet1!W30 -> 0 | G30: =HYPERLINK("https://www.google.com/maps/dir/Current+Location/"&J30,"Get Directions") -> Get Directions | I30: =Sheet1!A30 -> Jimmerson | J30: =Sheet1!B30 -> Abby
A31: =Sheet1!D31 -> 19-000694 | B31: =Sheet1!X31 -> 09/16/2025 | C31: =Sheet1!E31 -> 0 | D31: =Sheet1!W31 -> 0 | G31: =HYPERLINK("https://www.google.com/maps/dir/Current+Location/"&J31,"Get Directions") -> Get Directions | I31: =Sheet1!A31 -> Cagle | J31: =Sheet1!B31 -> Sara
A32: =Sheet1!D32 -> 21-000066 | B32: =Sheet1!X32 -> 45916 | C32: =Sheet1!E32 -> 0 | D32: =Sheet1!W32 -> 0 | G32: =HYPERLINK("https://www.google.com/maps/dir/Current+Location/"&J32,"Get Directions") -> Get Directions | I32: =Sheet1!A32 -> Mogonye | J32: =Sheet1!B32 -> Mason
A33: =Sheet1!D33 -> 22-002744 | B33: =Sheet1!X33 -> 09/16/2025 | C33: =Sheet1!E33 -> 0 | D33: =Sheet1!W33 -> 0 | G33: =HYPERLINK("https://www.google.com/maps/dir/Current+Location/"&J33,"Get Directions") -> Get Directions | I33: =Sheet1!A33 -> Zarola | J33: =Sheet1!B33 -> Aidan
A34: =Sheet1!D34 -> 0 | B34: =Sheet1!X34 -> 0 | C34: =Sheet1!E34 -> 0 | D34: =Sheet1!W34 -> 0 | G34: =HYPERLINK("https://www.google.com/maps/dir/Current+Location/"&J34,"Get Directions") -> Get Directions | I34: =Sheet1!A34 -> 0 | J34: =Sheet1!B34 -> 0
A35: =Sheet1!D35 -> 0 | B35: =Sheet1!X35 -> 0 | C35: =Sheet1!E35 -> 0 | D35: =Sheet1!W35 -> 0 | G35: =HYPERLINK("https://www.google.com/maps/dir/Current+Location/"&J35,"Get Directions") -> Get Directions | I35: =Sheet1!A35 -> 0 | J35: =Sheet1!B35 -> 0
A36: =Sheet1!D36 -> 0 | B36: =Sheet1!X36 -> 0 | D36: =Sheet1!W36 -> 0 | G36: =HYPERLINK("https://www.google.com/maps/dir/Current+Location/"&J36,"Get Directions") -> Get Directions | I36: =Sheet1!A36 -> 0 | J36: =Sheet1!B36 -> 0
A37: =Sheet1!D37 -> 0 | B37: =Sheet1!X37 -> 0 | D37: =Sheet1!W37 -> 0 | G37: =HYPERLINK("https://www.google.com/maps/dir/Current+Location/"&J37,"Get Directions") -> Get Directions | I37: =Sheet1!A37 -> 0 | J37: =Sheet1!B37 -> 0
A38: =Sheet1!D38 -> 0 | B38: =Sheet1!X38 -> 0 | D38: =Sheet1!W38 -> 0 | G38: =HYPERLINK("https://www.google.com/maps/dir/Current+Location/"&J38,"Get Directions") -> Get Directions | I38: =Sheet1!A38 -> 0 | J38: =Sheet1!B38 -> 0
A39: =Sheet1!D39 -> 0 | B39: =Sheet1!X39 -> 0 | D39: =Sheet1!W39 -> 0 | G39: =HYPERLINK("https://www.google.com/maps/dir/Current+Location/"&J39,"Get Directions") -> Get Directions | I39: =Sheet1!A39 -> 0 | J39: =Sheet1!B39 -> 0
A40: =Sheet1!D40 -> 0 | B40: =Sheet1!X40 -> 0 | D40: =Sheet1!W40 -> 0 | G40: =HYPERLINK("https://www.google.com/maps/dir/Current+Location/"&J40,"Get Directions") -> Get Directions | I40: =Sheet1!A40 -> 0 | J40: =Sheet1!B40 -> 0
...

Sheet Sheet3
