Workbook

Sheet Sheet1
A1: wardlast | B1: wardfirst | C1: wardmiddle | D1: causeno | E1: visitdate | F1: visittime | G1: wtele | H1: liveswith | I1: waddress | J1: wdob | K1: guardian1 | L1: gaddress | M1: gemail | N1: gtele | O1: Relationship | P1: gdob | Q1: Guardian2 | R1: g2 address | S1: g2eamil | T1: g2tele | U1: g2Relationship | V1: g2dob | W1: datesubmitted | X1: Dateappointed | Y1: miles | Z1: expense submitted | AA1: expensepd | AB1: Date ARP filed | AC1: Comments | AD1: CVR created? | AE1: emailsent | AF1: Appt_confirmed | AG1: Contact_added
A2: Wagner | B2: John Carter | D2: 21-001411 | E2: 45883 | F2: 45884 | G2: 512-514-4444 | H2: parents | I2: 412 Cargill Dr., Spicewood, TX 78699 | J2: 37842 | K2: Wagner, Todd and Sara | L2: 412 Cargill Dr., Spicewood, TX 78699 | M2: txgirl14boys@gmail.com | N2: 320-808-9453 | O2: Father/Mother | P2: 9/28/1973 5/01/1976 | W2: 45883 | X2: 45875 | AD2: Y | AE2: Y | AF2: Y | AG2: Y
A3: Dennis | B3: Abigail | D3: 17-000729 | E3: 45883 | F3: 15:45:00 | G3: 512-202-9638 | H3: parents | I3: 11508 Shoreview Overlook, Austin, TX | J3: 36252 | K3: Dennis, Joe and Lisa | L3: 11508 Shoreview Overlook, Austin, TX 78732 | M3: ljdenis214@gmail.com | N3: 512-808-8823 512-808-8821 | O3: Father/Mother | P3: 7/5/1971 2/14/1972 | W3: 45885 | X3: 45875 | AD3: Y | AE3: Y | AF3: Y | AG3: Y
A4: Halford | B4: Jon Tyler | D4: 22-001301 | E4: 45877 | F4: 15:30:00 | G4: 612-387-1813 | H4: parents | I4: 1700 Amis Ave, Austin, TX 78734 | J4: 38373 | K4: Halford, Jonnie and Amy | L4: 1700 Amis Ave, Austin, TX 78734 | M4: amyhalford710@gmail.com | N4: 612-387-1813 | O4: Father/Mother | P4: 12/17/1976 9/30/1976 | Q4: Lives in gated community, apppears happy nd says he is happy. Active in sports, work and walks dog. | W4: 45877 | X4: 45875 | AD4: Y | AE4: Y | AF4: Y | AG4: Y
A5: Braden | B5: Daniel | D5: 22-002249 | E5: 45882 | F5: 12:00:00 | H5: nursing home | I5: Barton Valley Rehab & HC 4501 Dudmar Dr., Austin, TX 78735 | J5: 1/03/1959q | K5: Mir Senior Care & Care Consultants | L5: 3410 Far West Blvd, Suite 120, Austin TX | M5: lina@mircareconsultants.com | O5: Professional Guardian | Q5: Kristin Martinelli,was case manager for long time 512.694.7448 Now Emmy Ledbetter 512.234.5515 | W5: 45882 | X5: 45875 | AD5: Y | AE5: Y | AF5: Y | AG5: Y
A6: Conner | B6: Julian Mayerik | D6: 16-000206 | E6: 45882 | F6: 14:30:00 | G6: 503-853-2788 | H6: parents | I6: 4509 Tambre Bnd, Austin, TX 78738 | J6: 9/9//98 | K6: Val Mayerick Tatiana Mayerik | L6: 4509 Tambre Bnd, Austin, TX 78738 | M6: valmayerik@gmail.com | N6: 971-506-8665 503-853-2788 | O6: Father/Mother | P6: 3/29/1950 8/20/1960 | W6: 45883 | X6: 45876 | AD6: Y | AE6: Y | AF6: Y | AG6: Y
A7: De Jong | B7: Brendan James | D7: 14-002049 | E7: 45892 | F7: 15:00:00 | H7: mother | I7: 15905 Chateau Ave, Austin, TX | J7: 35791 | K7: Kimberly Ellison De Jong | L7: 15905 Chateau Ave, Austin, Texas 78734 | M7: kedejong@msn.com | N7: 240-418-2233 | O7: Mother | P7: 22374 | W7: 45892 | X7: 45881 | AD7: Y | AE7: Y | AF7: Y | AG7: Y
A8: Eudy | B8: Kimberly Grace | D8: 06-084450 | E8: 45884 | F8: 13:00:00 | G8: 512-925-9215 | H8: apartment | I8: Avanti Hills at the Galleria 12601 Bee Cave Parkway, Apt 2-225 BeeCave, TX 78738 | J8: 32230 | K8: Eudy Kimberly H | L8: 121 Lido street, Austin, TX 78734 | M8: braden ca | N8: 512-940-2545 | O8: Mother | P8: 20776 | W8: 45886 | X8: 45881 | AD8: Y | AE8: Y | AF8: Y | AG8: Y
A9: Jones | B9: Andrew Colton | D9: 20-001710 | E9: 45884 | F9: 14:00:00 | G9: 512-565-3313 | H9: apartment | I9: Avanti Hills at the Galleria 12601 Bee Cave Parkway, Apt 243 Bee Cave TX 78738 | J9: 37542 | K9: Jones, Andrew P. | L9: 303 Bellagio Dr, Austin, TX 78734 | M9: apjon1@yahoo.com | N9: 832-3167953 | O9: Father | P9: 24153 | W9: 45886 | X9: 45881 | AD9: Y | AE9: Y | AF9: Y | AG9: Y
A10: Park | B10: Mina | D10: 18-001798 | E10: 45884 | F10: 12:00:00 | G10: 512-815-8640 | H10: assisted living | I10: 107 Bella Montagna Circle, Lakeway, TX | J10: 10861 | K10: Park, Randal Michael | L10: 1306 Fernglade Lane, Cedar Park, TX 78613 | M10: randalpark@yahoo.com | N10: 512-848-3024 | O10: Son | P10: 21307 | W10: 45886 | X10: 45881 | AC10: Lives in Belmont Village AL, 95 yr old potential need to move to memory care | AD10: Y | AE10: Y | AF10: Y | AG10: Y
A11: Bennett | B11: Luke Thomas | D11: 19-000060 | E11: 45884 | F11: 10:00:00 | G11: 512-762-5949 | H11: parents | I11: 4300 Hennig Dr, Austin, TX 78738 | J11: 36929 | K11: Thomas, Brad and Courtney | L11: 4300 Hennig Drive, Austin, TX 78738 | M11: courtneythomasou91@gmail.com | N11: 512-762-5949 | O11: Father/Mother | P11: 7/28/1969 10/13/1968 | W11: 45885 | X11: 45881 | AD11: Y | AE11: Y | AF11: Y | AG11: Y
A12: Davidson | B12: Anthony Michael | D12: 15-002046 | E12: 45896 | F12: 12:00:00 | G12: 512-826-1260 | H12: parents | I12: 6008 Gunnison Turn Rd, Austin, TX 78738 | J12: 35729 | K12: Davidson, Marcela | L12: 6008 Gunnison Turn Rd, Austin, TX 78738 | M12: mdavidson7@austin.rr.com | N12: 512-317-4727 | O12: Mother | P12: 24110 | Q12: marcydavidson531@gmail.com | W12: 45896 | X12: 45888 | AD12: Y | AE12: Y | AF12: Y | AG12: Y
A14: Hall | B14: Alexandra | D14: 08-088136 | E14: 45896 | F14: 15:00:00 | H14: parents | I14: 2 Prestonwood Circle, Lakeway, TX 78737 | J14: 32931 | K14: Hall Kari | L14: 2 Prestonwood Circle, Lakewy, TX 78737 | N14: 512-560-4256 | O14: Mother | P14: 22119 | Q14: Hall, Derek | R14: 3 Prestonwood Circle, Lakewy, TX 78737 | U14: Father | V14: 20537 | W14: 45896 | X14: 45888 | AD14: Y | AE14: Y | AF14: Y | AG14: Y
A15: Jain | B15: Ryan | D15: 24-001242 | E15: 45896 | F15: 14:00:00 | H15: parents | I15: 105 Bel Lago Cove, Austin, TX 78734 | J15: 38911 | K15: Jain Meenu | L15: 105 Bel Lago Cove, Austin, TX 78734 | M15: meenu.jain@gmail.com | N15: 512-786-3084 | O15: Father | P15: 27696 | Q15: Jain, Ankur | R15: 105 Bel Lago Cove, Austin, TX 78734 | S15: ankur.ankurjain@gmail.com | T15: 512-743-1849 | U15: Mother | V15: 27465 | W15: 45896 | X15: 45888 | AD15: Y | AE15: Y | AF15: Y | AG15: Y
A16: Loy | B16: Mary K. | D16: 09-000016 | E16: 45897 | F16: 13:30:00 | G16: 512-743-7711 | H16: parents | I16: 208 Darwins Way, Lakeway, TX, 78734 | J16: 20884 | K16: Loy, Charles E. | L16: 208 Darwins Way, Lakeway, TX, 78734 | M16: melyssaloy@mac.com | N16: 512-743-1845 | O16: Father | P16: 21311 | Q16: Loy, Melyssa | R16: 209 Darwins Way, Lakeway, TX, 78734 | U16: Mother | W16: 45897 | X16: 45888 | AD16: Y | AE16: Y | AF16: Y | AG16: Y
A17: Taylor | B17: Ryan Matthew | D17: 22-000706 | E17: 45896 | F17: 16:00:00 | G17: 512-791-7251 | H17: parents | I17: 6416 Llano Stage Trl, Austin, TX 78738 | J17: 38124 | K17: Taylor Brian | L17: 6416 Llano Stage Trl, Austin, TX 78738 | N17: 512-415-7754 | O17: Father | P17: 24820 | Q17: Taylor, Nicole | R17: 6416 Llano Stage Trl, Austin, TX 78738 | S17: nktaylor76@gmail.com | T17: 512-791-7251 | U17: Mother | V17: 27982 | W17: 45896 | X17: 45888 | AD17: Y | AE17: Y | AF17: Y | AG17: Y
A18: Turnbaugh | B18: Elizabeth | D18: 00-074302 | E18: 45896 | F18: 17:00:00 | H18: parents | I18: 22 Hedgebrook Way, Austin, TX 78738 | J18: 31904 | K18: Turnbaugh, Jill | L18: 22 Hedgebrook Way, Austin, TX 78738 | O18: Mother | P18: 19757 | Q18: Turnbaugh, Dean | R18: 22 Hedgebrook Way, Austin, TX 78738 | U18: Father | V18: 20048 | W18: 45896 | X18: 45888 | AD18: Y | AE18: Y | AF18: Y
A19: Warren | B19: David Patrick | D19: 23-000357 | E19: 45897 | F19: 14:30:00 | H19: parents | I19: 13213 Country Lake Drive, Austin, TX 78732 | J19: 38390 | K19: Warren, Phillip Bowman | L19: 13213 Country Lake Drive, Austin, TX 78732 | N19: 512-963-6504 | O19: Father | P19: 22227 | Q19: Warren, Julie Powell | R19: 13213 Country Lake Drive, Austin, TX 78732 | S19: juliepowellwarren@gmail.com | T19: 512-461-3015 | U19: Mother | V19: 23237 | W19: 45897 | X19: 45888 | AD19: Y | AE19: Y | AF19: Y | AG19: Y
A20: Luna | B20: Oscar | D20: 05-82942 | E20: 45903 | F20: 15:00:00 | H20: Mother | I20: 2406 Monarch Dr, Austin, TX 78748 | J20: 31916 | K20: Medel, Catalina | L20: 2406 Monarch Dr, Austin, TX 78748 | M20: medelc64@gmail.com | N20: 512-282-1208 | O20: Mother | P20: 23486 | W20: 45904 | X20: t | AD20: Y | AE20: Y | AF20: Y | AG20: Y
A21: Brener | B21: Benjamin | D21: 06-085777 | E21: 45905 | F21: 16:00:00 | I21: 2404 Roe hampton Dr., Austin, TX 78745 | J21: 32518 | K21: Brener, Fay | L21: 4040 Enclave Mesa Circle, Austin, TX 78731 | M21: brefaye@hotmail.com | N21: 512-338-0176 | O21: Mother | P21: 20843 | Q21: Brener, Lazaro | R21: 4040 Enclave Mesa Circle, Austin, TX 78731 | S21: lazarbre@hotmail.com | U21: father | V21: 17061 | W21: 45908 | X21: 45896 | AB21: 45727 | AD21: Y | AE21: Y | AF21: Y | AG21: Y
A22: Potter | B22: Mark | D22: 09-001594 | E22: 45905 | F22: 17:00:00 | G22: 512-789-4079 | H22: Mark I Residential Services Group Home | I22: 2517 McGregor Lane, Austin, TX 78745 | J22: 20160 | K22: Family Eldercare, Inc. Chrisi Johnson, Care Manager | L22: 1700 Rutherford Ln, Austin, TX 78754 | M22: cjohnson@familyeldercare.org | N22: 512-628-1693 | W22: 45908 | X22: 45897 | AB22: 45747 | AD22: Y | AE22: Y | AF22: Y | AG22: Y
A23: Reich | B23: Quinn | D23: 14-000172 | E23: 45908 | F23: 14:30:00 | G23: 512-517-5680 | H23: own home | I23: 6008 Rutledge Ln, Austin, TX 78745 | J23: 35094 | K23: LeBoeuf | L23: 5120 Concho Creek Bend, Austin, TX 78735 | M23: lleboeuf0807@gmail.com | N23: 512-517-5680 | O23: parent | P23: 22865 | Q23: Reich, Stephanie | R23: 205 Laurelwood Trail, Austin, TX 78746 | T23: 512-306-7314 | V23: 22712 | W23: 45908 | X23: 45897 | AB23: 45821 | AD23: Y | AE23: Y | AF23: Y | AG23: Y
A24: Cox | B24: Ty | D24: 15-000428 | E24: 45904 | F24: 16:00:00 | G24: 512-698-0502 | H24: mother and father | I24: 4415 Huffman Drive, Austin, TX 78749 | J24: 33381 | K24: Cox, Matthew | L24: 4415 Hoffman Drive, Austin, TX 78749 | M24: mattjoncox@gmail.com | N24: 512-698-0502 | O24: father | P24: 23892 | Q24: Cox, Amy | R24: 4415 Hoffman Dr., Austin, TX 78749 | S24: amykcox1964@gmail.com | U24: mother | V24: 23613 | W24: 45904 | X24: 45897 | AB24: 45810 | AD24: Y | AE24: Y | AF24: Y | AG24: Y
A25: Roberts | B25: Jay | D25: 17-000201 | E25: 45904 | F25: 13:00:00 | G25: 512-560-2265 | H25: father/mother | I25: 6452 Ruxton Ln, Austin, TX 78749 | J25: 36216 | K25: Roberts, Jay | L25: 6452 Ruxton Ln, Austin, TX 78749 | M25: streboryaj@gmail.com | N25: 512-417-2350 | O25: father | P25: 24667 | Q25: Roberts, Ellen | R25: 6452 Ruxton Ln, Austin, TX 78749 | S25: strebornelle@gmail.com | T25: 512-560-2265 | U25: mother | V25: 26443 | W25: 45904 | X25: 45896 | AB25: 45726 | AD25: Y | AE25: Y | AF25: Y | AG25: Y
A26: Toney | B26: Emma | D26: 18-000194 | E26: 45903 | F26: 17:00:00 | G26: 512-585-8505 | H26: father/mother | I26: 570 Woodland Dr., Driftwood, TX 78619 | J26: 35690 | K26: Toney, Derrick | L26: 570 Woodland Dr., Driftwood, TX 78619 | M26: datoney2@gmail.com | N26: 512-585-8505 | O26: father | P26: 23758 | Q26: Toney, Sara Jane | R26: 570 Woodland Dr., Driftwood, TX 78619 | W26: 45904 | X26: 45897 | AB26: 45684 | AD26: Y | AE26: Y | AF26: Y | AG26: Y
A27: Huerta | B27: Gabriela | D27: 19-002069 | E27: 45904 | F27: 18:30:00 | G27: 512-497-3944 | H27: father/mother | I27: 8800 Ravello Pass, Austin, TX 78749 | J27: 37074 | K27: Huerta, Julian | L27: 6207 Old Harbor, Austin, TX 78739 | N27: 512-826-1616 | O27: father | P27: 23998 | Q27: Huerta Isabel | R27: 8800 Ravello Pass, Austin, TX 78749 | S27: i.huerta@sammyshouse.com | T27: 512-497-3944 | U27: mother | V27: 21954 | W27: 45908 | X27: 45896 | AB27: 45744 | AD27: Y | AE27: Y | AF27: Y | AG27: Y
A28: Ximenez | B28: Jose | D28: 99-071988 | E28: 45905 | F28: 17:30:00 | G28: 512-448-9559 | H28: Mark I Residential Services Group Home | I28: 2517 McGregor Dr., Austin, TX 78745 | J28: 29809 | K28: Family Eldercare Robert Lontkowski, Care Manager | L28: 1700 Rutherford Ln, Austin, TX 78754 | M28: rlontkowski@familyeldercare.org | N28: 512-483-3564 | O28: Public Guardian | W28: 45908 | X28: 45897 | AB28: 45740 | AC28: case manager is Mark Henson mrk1res@swbell.net Jeanette is staff after 4 pm | AD28: Y | AE28: Y | AF28: Y | AG28: Y
A29: Wolk | B29: James | C29: David | D29: 05-082943 | E29: 45965 | F29: 0.52083333 | G29: (512) 914-5464 | H29: Guardian | I29: 101 AcapulcoCourt, Austin. TX 78734 | J29: 01/23/1987 | K29: If Co-guardians | L29: 101AcapulcoCourt, Austin. TX 78734 | M29: magda.wolk@gmail.com | N29: (512) 914-5464 | O29: : Mom | P29: 08/07/1951 | X29: 09/16/2025 | AB29: 07/22/2025 | AC29: 2025-10-02 10:41:56 | AD29: Y | AE29: 2025-10-03 | AG29: Y
A30: Jimmerson | B30: Abby | C30: Marie | D30: 13-000934 | E30: 45975 | F30: 0.625 | G30: (512) 923-6754 | H30: parents | I30: 3204 Oksheer Dr., Austin, TX 78732 | J30: 06/09/1995 | K30: Jimmerson, Gwendelynn | L30: 3204 Oksheer Dr., Austin, TX 78732 | M30: wendyjimmerson@gmail.com | N30: 512-923-6754 | O30: Mom | P30: 24139 | Q30: James Jimmerson | R30: 3204 Oksheer Dr., Austin, TX 78732 | T30: 512-914-0943 | U30: Father | V30: 23096 | X30: 09/16/2025 | AB30: 07/21/2025 | AC30: 2025-10-02 10:41:58 | AD30: Y | AE30: 2025-10-03 | AG30: Y
A31: Cagle | B31: Sara | C31: Elliott | D31: 19-000694 | E31: 45967 | F31: 0.6875 | G31: (713) 380-7865 | H31: parents | I31: 9303 Scenic Bluff Dr., Austin, Texas 78733 | J31: 06/21/2001 | K31: Cagle, Thomas Patrick | L31: 9303 Scenic Bluff Dr., Austin, Texas 78733 | M31: tpcaglejr@gmail.com | N31: 713-380-7865 | O31: Father | P31: 08/16/1965 | Q31: Nicole Cagle | R31: 9303 Scenic Bluff Dr., Austin, Texas 78733 | S31: none | T31: none | U31: Mother | V31: 04/15/1965 | X31: 09/16/2025 | AB31: 45859 | AC31: 2025-10-02 10:41:59 | AD31: Y | AE31: 2025-10-03 | AG31: Y
A32: Mogonye | B32: Mason | C32: Todd | D32: 21-000066 | E32: 45966 | F32: 0.66666667 | G32: (737) 230-6831 | H32: parents | I32: 12834 Texas Sage Court, Austin, TX | J32: 03/14/2003 | K32: Mogonye, Michael | L32: 12834 Texas Sage Court, Austin, TX | M32: JeM0801@gmail.com | N32: (512) 694-6202 | O32: Father | P32: 28077 | Q32: Joslyne Mogonye | R32: 12834 Texas Sage Court, Austin, TX | S32: none | T32: (512) 771-1695 | U32: Mother | V32: 26735 | X32: 45916 | AB32: 45834 | AC32: 2025-10-02 10:41:17 | AD32: Y | AE32: 2025-10-03 | AG32: Y
A33: Zarola | B33: Aidan | C33: Jack | D33: 22-002744 | E33: 45965 | F33: 0.58333333 | G33: (619) 316-2897 | H33: parents | I33: 104 Largo Cove, Austin/TX/78734 | J33: 08/20/2000 | K33: Zarola, Michael | L33: 104 Largo Cove, Austin/TX/78734 | M33: thezarolas@gmail.com | N33: (619) 316-2897 | O33: Father | P33: 26596 | Q33: Veronica Zarola | R33: 104 Largo Cove, Austin/TX/78734 | S33: none | T33: none | U33: Mother | V33: 25830 | X33: 09/16/2025 | AB33: 45869 | AC33: 2025-10-02 10:42:02 | AD33: Y | AE33: 2025-10-03 | AG33: Y
A34: Dodson | B34: Michael Todd | D34: 12-000189 | E34: 45967 | F34: 0.64583333 | G34: 512-435-7969 | H34: Mother | I34: 900 Elder Circle, Austin, TX 78733 | J34: 34415 | K34: Mooring, Elisa Berkman | L34: 900 Elder Circle, Austin, TX 78733 | M34: lismooring@aol.com | N34: 512-435-7969 | O34: Mother | P34: 23235 | Q34: Davidson, Daniel | R34: 6009 Gunnison Turn Rd, Austin, TX 78738 | S34: danieldavidson879@gmail.com | T34: 512-826-1260 | U34: Father | V34: 23893 | W34: tbd | X34: 45888 | AC34: Cannot schedule until October at horseback riding camp | AD34: Y | AE34: Y | AF34: Y | AG34: Y

Sheet Sheet2
A1: causeno | B1: dateappointed | C1: visitdate | D1: datesubmitted | G1: directions | I1: name
A2: =Sheet1!D2 -> 21-001411 | B2: =Sheet1!X2 -> 45875 | C2: =Sheet1!E2 -> 45883 | D2: =Sheet1!W2 -> 45883 | G2: =HYPERLINK("https://www.google.com/maps/dir//''/data=!4m7?q="&J2,"Get Directions") -> Get Directions | I2: =Sheet1!A2 -> Wagner | J2: =Sheet1!B2 -> John Carter
A3: =Sheet1!D3 -> 17-000729 | B3: =Sheet1!X3 -> 45875 | C3: =Sheet1!E3 -> 45883 | D3: =Sheet1!W3 -> 45885 | G3: =HYPERLINK("https://www.google.com/maps/dir/Current+Location/"&J3,"Get Directions") -> Get Directions | I3: =Sheet1!A3 -> Dennis | J3: =Sheet1!B3 -> Abigail
A4: =Sheet1!D4 -> 22-001301 | B4: =Sheet1!X4 -> 45875 | C4: =Sheet1!E4 -> 45877 | D4: =Sheet1!W4 -> 45877 | G4: =HYPERLINK("https://www.google.com/maps/dir/Current+Location/"&J4,"Get Directions") -> Get Directions | I4: =Sheet1!A4 -> Halford | J4: =Sheet1!B4 -> Jon Tyler
A5: =Sheet1!D5 -> 22-002249 | B5: =Sheet1!X5 -> 45875 | C5: =Sheet1!E5 -> 45882 | D5: =Sheet1!W5 -> 45882 | G5: =HYPERLINK("https://www.google.com/maps/dir/Current+Location/"&J5,"Get Directions") -> Get Directions | I5: =Sheet1!A5 -> Braden | J5: =Sheet1!B5 -> Daniel
A6: =Sheet1!D6 -> 16-000206 | B6: =Sheet1!X6 -> 45876 | C6: =Sheet1!E6 -> 45882 | D6: =Sheet1!W6 -> 45883 | G6: =HYPERLINK("https://www.google.com/maps/dir/Current+Location/"&J6,"Get Directions") -> Get Directions | I6: =Sheet1!A6 -> Conner | J6: =Sheet1!B6 -> Julian Mayerik
A7: =Sheet1!D7 -> 14-002049 | B7: =Sheet1!X7 -> 45881 | C7: =Sheet1!E7 -> 45892 | D7: =Sheet1!W7 -> 45892 | G7: =HYPERLINK("https://www.google.com/maps/dir/Current+Location/"&J7,"Get Directions") -> Get Directions | I7: =Sheet1!A7 -> De Jong | J7: =Sheet1!B7 -> Brendan James
A8: =Sheet1!D8 -> 06-084450 | B8: =Sheet1!X8 -> 45881 | C8: =Sheet1!E8 -> 45884 | D8: =Sheet1!W8 -> 45886 | G8: =HYPERLINK("https://www.google.com/maps/dir/Current+Location/"&J8,"Get Directions") -> Get Directions | I8: =Sheet1!A8 -> Eudy | J8: =Sheet1!B8 -> Kimberly Grace
A9: =Sheet1!D9 -> 20-001710 | B9: =Sheet1!X9 -> 45881 | C9: =Sheet1!E9 -> 45884 | D9: =Sheet1!W9 -> 45886 | G9: =HYPERLINK("https://www.google.com/maps/dir/Current+Location/"&J9,"Get Directions") -> Get Directions | I9: =Sheet1!A9 -> Jones | J9: =Sheet1!B9 -> Andrew Colton
A10: =Sheet1!D10 -> 18-001798 | B10: =Sheet1!X10 -> 45881 | C10: =Sheet1!E10 -> 45884 | D10: =Sheet1!W10 -> 45886 | G10: =HYPERLINK("https://www.google.com/maps/dir/Current+Location/"&J10,"Get Directions") -> Get Directions | I10: =Sheet1!A10 -> Park | J10: =Sheet1!B10 -> Mina
A11: =Sheet1!D11 -> 19-000060 | B11: =Sheet1!X11 -> 45881 | C11: =Sheet1!E11 -> 45884 | D11: =Sheet1!W11 -> 45885 | G11: =HYPERLINK("https://www.google.com/maps/dir/Current+Location/"&J11,"Get Directions") -> Get Directions | I11: =Sheet1!A11 -> Bennett | J11: =Sheet1!B11 -> Luke Thomas
A12: =Sheet1!D12 -> 15-002046 | B12: =Sheet1!X12 -> 45888 | C12: =Sheet1!E12 -> 45896 | D12: =Sheet1!W12 -> 45896 | G12: =HYPERLINK("https://www.google.com/maps/dir/Current+Location/"&J12,"Get Directions") -> Get Directions | I12: =Sheet1!A12 -> Davidson | J12: =Sheet1!B12 -> Anthony Michael
A13: =Sheet1!D34 -> 12-000189 | B13: =Sheet1!X34 -> 45888 | C13: =Sheet1!E34 -> 45967 | D13: =Sheet1!W34 -> tbd | G13: =HYPERLINK("https://www.google.com/maps/dir/Current+Location/"&J13,"Get Directions") -> Get Directions | I13: =Sheet1!A34 -> Dodson | J13: =Sheet1!B34 -> Michael Todd
A14: =Sheet1!D14 -> 08-088136 | B14: =Sheet1!X14 -> 45888 | C14: =Sheet1!E14 -> 45896 | D14: =Sheet1!W14 -> 45896 | G14: =HYPERLINK("https://www.google.com/maps/dir/Current+Location/"&J14,"Get Directions") -> Get Directions | I14: =Sheet1!A14 -> Hall | J14: =Sheet1!B14 -> Alexandra
A15: =Sheet1!D15 -> 24-001242 | B15: =Sheet1!X15 -> 45888 | C15: =Sheet1!E15 -> 45896 | D15: =Sheet1!W15 -> 45896 | G15: =HYPERLINK("https://www.google.com/maps/dir/Current+Location/"&J15,"Get Directions") -> Get Directions | I15: =Sheet1!A15 -> Jain | J15: =Sheet1!B15 -> Ryan
A16: =Sheet1!D16 -> 09-000016 | B16: =Sheet1!X16 -> 45888 | C16: =Sheet1!E16 -> 45897 | D16: 45897 | G16: =HYPERLINK("https://www.google.com/maps/dir/Current+Location/"&J16,"Get Directions") -> Get Directions | I16: =Sheet1!A16 -> Loy | J16: =Sheet1!B16 -> Mary K.
A17: =Sheet1!D17 -> 22-000706 | B17: =Sheet1!X17 -> 45888 | C17: =Sheet1!E17 -> 45896 | D17: =Sheet1!W17 -> 45896 | G17: =HYPERLINK("https://www.google.com/maps/dir/Current+Location/"&J17,"Get Directions") -> Get Directions | I17: =Sheet1!A17 -> Taylor | J17: =Sheet1!B17 -> Ryan Matthew
A18: =Sheet1!D18 -> 00-074302 | B18: =Sheet1!X18 -> 45888 | C18: =Sheet1!E18 -> 45896 | D18: =Sheet1!W18 -> 45896 | G18: =HYPERLINK("https://www.google.com/maps/dir/Current+Location/"&I18,"Get Directions") -> Get Directions | I18: =Sheet1!A18 -> Turnbaugh | J18: =Sheet1!B18 -> Elizabeth
A19: =Sheet1!D19 -> 23-000357 | B19: =Sheet1!X19 -> 45888 | C19: =Sheet1!E19 -> 45897 | D19: 45897 | G19: =HYPERLINK("https://www.google.com/maps/dir/Current+Location/"&J19,"Get Directions") -> Get Directions | I19: =Sheet1!A19 -> Warren | J19: =Sheet1!B19 -> David Patrick
A20: =Sheet1!D21 -> 06-085777 | B20: =Sheet1!X20 -> t | C20: =Sheet1!E20 -> 45903 | D20: =Sheet1!W20 -> 45904 | G20: =HYPERLINK("https://www.google.com/maps/dir/Current+Location/"&J20,"Get Directions") -> Get Directions | I20: =Sheet1!A20 -> Luna | J20: =Sheet1!B20 -> Oscar | L20: Luna
A21: =Sheet1!D22 -> 09-001594 | B21: =Sheet1!X21 -> 45896 | C21: =Sheet1!E21 -> 45905 | D21: =Sheet1!W21 -> 45908 | I21: =Sheet1!A21 -> Brener | J21: =Sheet1!B21 -> Benjamin | L21: Brener
A22: =Sheet1!D22 -> 09-001594 | B22: =Sheet1!X22 -> 45897 | C22: =Sheet1!E22 -> 45905 | D22: =Sheet1!W22 -> 45908 | G22: =HYPERLINK("https://www.google.com/maps/dir/Current+Location/"&J22,"Get Directions") -> Get Directions | I22: =Sheet1!A22 -> Potter | J22: =Sheet1!B22 -> Mark | L22: Potter
A23: =Sheet1!D23 -> 14-000172 | B23: =Sheet1!X23 -> 45897 | C23: =Sheet1!E23 -> 45908 | D23: =Sheet1!W23 -> 45908 | G23: =HYPERLINK("https://www.google.com/maps/dir/Current+Location/"&J23,"Get Directions") -> Get Directions | I23: =Sheet1!A23 -> Reich | J23: =Sheet1!B23 -> Quinn | L23: Reich
A24: =Sheet1!D24 -> 15-000428 | B24: =Sheet1!X24 -> 45897 | C24: =Sheet1!E24 -> 45904 | D24: =Sheet1!W24 -> 45904 | G24: =HYPERLINK("https://www.google.com/maps/dir/Current+Location/"&J24,"Get Directions") -> Get Directions | I24: =Sheet1!A24 -> Cox | J24: =Sheet1!B24 -> Ty | L24: Cox
A25: =Sheet1!D25 -> 17-000201 | B25: =Sheet1!X25 -> 45896 | C25: =Sheet1!E25 -> 45904 | D25: =Sheet1!W25 -> 45904 | G25: =HYPERLINK("https://www.google.com/maps/dir/Current+Location/"&J25,"Get Directions") -> Get Directions | I25: =Sheet1!A25 -> Roberts | J25: =Sheet1!B25 -> Jay | L25: Roberts
A26: =Sheet1!D26 -> 18-000194 | B26: =Sheet1!X26 -> 45897 | C26: =Sheet1!E26 -> 45903 | D26: =Sheet1!W26 -> 45904 | G26: =HYPERLINK("https://www.google.com/maps/dir/Current+Location/"&J26,"Get Directions") -> Get Directions | I26: =Sheet1!A26 -> Toney | J26: =Sheet1!B26 -> Emma | L26: Toney
A27: =Sheet1!D27 -> 19-002069 | B27: =Sheet1!X27 -> 45896 | C27: =Sheet1!E27 -> 45904 | D27: =Sheet1!W27 -> 45908 | G27: =HYPERLINK("https://www.google.com/maps/dir/Current+Location/"&J27,"Get Directions") -> Get Directions | I27: =Sheet1!A27 -> Huerta | J27: =Sheet1!B27 -> Gabriela | L27: Huerta
A28: =Sheet1!D28 -> 99-071988 | B28: =Sheet1!X28 -> 45897 | C28: =Sheet1!E28 -> 45905 | D28: =Sheet1!W28 -> 45908 | G28: =HYPERLINK("https://www.google.com/maps/dir/Current+Location/"&J28,"Get Directions") -> Get Directions | I28: =Sheet1!A28 -> Ximenez | J28: =Sheet1!B28 -> Jose | L28: Ximenez
A29: =Sheet1!D29 -> 05-082943 | B29: =Sheet1!X29 -> 09/16/2025 | C29: =Sheet1!E29 -> 45965 | D29: =Sheet1!W29 -> 0 | G29: =HYPERLINK("https://www.google.com/maps/dir/Current+Location/"&J29,"Get Directions") -> Get Directions | I29: =Sheet1!A29 -> Wolk | J29: =Sheet1!B29 -> James
A30: =Sheet1!D30 -> 13-000934 | B30: =Sheet1!X30 -> 09/16/2025 | C30: =Sheet1!E30 -> 45975 | D30: =Sheet1!W30 -> 0 | G30: =HYPERLINK("https://www.google.com/maps/dir/Current+Location/"&J30,"Get Directions") -> Get Directions | I30: =Sheet1!A30 -> Jimmerson | J30: =Sheet1!B30 -> Abby
A31: =Sheet1!D31 -> 19-000694 | B31: =Sheet1!X31 -> 09/16/2025 | C31: =Sheet1!E31 -> 45967 | D31: =Sheet1!W31 -> 0 | G31: =HYPERLINK("https://www.google.com/maps/dir/Current+Location/"&J31,"Get Directions") -> Get Directions | I31: =Sheet1!A31 -> Cagle | J31: =Sheet1!B31 -> Sara
A32: =Sheet1!D32 -> 21-000066 | B32: =Sheet1!X32 -> 45916 | C32: =Sheet1!E32 -> 45966 | D32: =Sheet1!W32 -> 0 | G32: =HYPERLINK("https://www.google.com/maps/dir/Current+Location/"&J32,"Get Directions") -> Get Directions | I32: =Sheet1!A32 -> Mogonye | J32: =Sheet1!B32 -> Mason
A33: =Sheet1!D33 -> 22-002744 | B33: =Sheet1!X33 -> 09/16/2025 | C33: =Sheet1!E33 -> 45965 | D33: =Sheet1!W33 -> 0 | G33: =HYPERLINK("https://www.google.com/maps/dir/Current+Location/"&J33,"Get Directions") -> Get Directions | I33: =Sheet1!A33 -> Zarola | J33: =Sheet1!B33 -> Aidan
A34: =Sheet1!#REF! -> #REF! | B34: =Sheet1!#REF! -> #REF! | C34: =Sheet1!E35 -> 0 | D34: =Sheet1!#REF! -> #REF! | G34: =HYPERLINK("https://www.google.com/maps/dir/Current+Location/"&J34,"Get Directions") -> #REF! | I34: =Sheet1!#REF! -> #REF! | J34: =Sheet1!#REF! -> #REF!
A35: =Sheet1!D35 -> 0 | B35: =Sheet1!X35 -> 0 | C35: =Sheet1!#REF! -> #REF! | D35: =Sheet1!W35 -> 0 | G35: =HYPERLINK("https://www.google.com/maps/dir/Current+Location/"&J35,"Get Directions") -> Get Directions | I35: =Sheet1!A35 -> 0 | J35: =Sheet1!B35 -> 0
A36: =Sheet1!D36 -> 0 | B36: =Sheet1!X36 -> 0 | D36: =Sheet1!W36 -> 0 | G36: =HYPERLINK("https://www.google.com/maps/dir/Current+Location/"&J36,"Get Directions") -> Get Directions | I36: =Sheet1!A36 -> 0 | J36: =Sheet1!B36 -> 0
A37: =Sheet1!D37 -> 0 | B37: =Sheet1!X37 -> 0 | D37: =Sheet1!W37 -> 0 | G37: =HYPERLINK("https://www.google.com/maps/dir/Current+Location/"&J37,"Get Directions") -> Get Directions | I37: =Sheet1!A37 -> 0 | J37: =Sheet1!B37 -> 0
A38: =Sheet1!D38 -> 0 | B38: =Sheet1!X38 -> 0 | D38: =Sheet1!W38 -> 0 | G38: =HYPERLINK("https://www.google.com/maps/dir/Current+Location/"&J38,"Get Directions") -> Get Directions | I38: =Sheet1!A38 -> 0 | J38: =Sheet1!B38 -> 0
A39: =Sheet1!D39 -> 0 | B39: =Sheet1!X39 -> 0 | D39: =Sheet1!W39 -> 0 | G39: =HYPERLINK("https://www.google.com/maps/dir/Current+Location/"&J39,"Get Directions") -> Get Directions | I39: =Sheet1!A39 -> 0 | J39: =Sheet1!B39 -> 0
A40: =Sheet1!D40 -> 0 | B40: =Sheet1!X40 -> 0 | D40: =Sheet1!W40 -> 0 | G40: =HYPERLINK("https://www.google.com/maps/dir/Current+Location/"&J40,"Get Directions") -> Get Directions | I40: =Sheet1!A40 -> 0 | J40: =Sheet1!B40 -> 0
...

Sheet Sheet3

Sheet Clients
A1: ClientID | B1: CauseNo | C1: WardFirst | D1: WardLast | E1: Status | F1: PrimaryEmail | G1: CCEmail | H1: ConsentToEmail | I1: DoNotEmailReason | J1: LastContacted | K1: NextFollowUp
B2: =Sheet1!D2 -> 21-001411 | C2: =Sheet1!B2 -> John Carter | D2: =Sheet1!A2 -> Wagner | F2: =Sheet1!M2 -> txgirl14boys@gmail.com | G2: =IF(Sheet1!S2="","",Sheet1!S2) | H2: =IF(Table1[[#This Row],[PrimaryEmail]]<>"","Yes","") -> Yes
B3: =Sheet1!D3 -> 17-000729 | C3: =Sheet1!B3 -> Abigail | D3: =Sheet1!A3 -> Dennis | F3: =Sheet1!M3 -> ljdenis214@gmail.com | G3: =IF(Sheet1!S3="","",Sheet1!S3) | H3: =IF(Table1[[#This Row],[PrimaryEmail]]<>"","Yes","") -> Yes
B4: =Sheet1!D4 -> 22-001301 | C4: =Sheet1!B4 -> Jon Tyler | D4: =Sheet1!A4 -> Halford | F4: =Sheet1!M4 -> amyhalford710@gmail.com | G4: =IF(Sheet1!S4="","",Sheet1!S4) | H4: =IF(Table1[[#This Row],[PrimaryEmail]]<>"","Yes","") -> Yes
B5: =Sheet1!D5 -> 22-002249 | C5: =Sheet1!B5 -> Daniel | D5: =Sheet1!A5 -> Braden | F5: =Sheet1!M5 -> lina@mircareconsultants.com | G5: =IF(Sheet1!S5="","",Sheet1!S5) | H5: =IF(Table1[[#This Row],[PrimaryEmail]]<>"","Yes","") -> Yes
B6: =Sheet1!D6 -> 16-000206 | C6: =Sheet1!B6 -> Julian Mayerik | D6: =Sheet1!A6 -> Conner | F6: =Sheet1!M6 -> valmayerik@gmail.com | G6: =IF(Sheet1!S6="","",Sheet1!S6) | H6: =IF(Table1[[#This Row],[PrimaryEmail]]<>"","Yes","") -> Yes
B7: =Sheet1!D7 -> 14-002049 | C7: =Sheet1!B7 -> Brendan James | D7: =Sheet1!A7 -> De Jong | F7: =Sheet1!M7 -> kedejong@msn.com | G7: =IF(Sheet1!S7="","",Sheet1!S7) | H7: =IF(Table1[[#This Row],[PrimaryEmail]]<>"","Yes","") -> Yes
B8: =Sheet1!D8 -> 06-084450 | C8: =Sheet1!B8 -> Kimberly Grace | D8: =Sheet1!A8 -> Eudy | F8: =Sheet1!M8 -> braden ca | G8: =IF(Sheet1!S8="","",Sheet1!S8) | H8: =IF(Table1[[#This Row],[PrimaryEmail]]<>"","Yes","") -> Yes
B9: =Sheet1!D9 -> 20-001710 | C9: =Sheet1!B9 -> Andrew Colton | D9: =Sheet1!A9 -> Jones | F9: =Sheet1!M9 -> apjon1@yahoo.com | G9: =IF(Sheet1!S9="","",Sheet1!S9) | H9: =IF(Table1[[#This Row],[PrimaryEmail]]<>"","Yes","") -> Yes
B10: =Sheet1!D10 -> 18-001798 | C10: =Sheet1!B10 -> Mina | D10: =Sheet1!A10 -> Park | F10: =Sheet1!M10 -> randalpark@yahoo.com | G10: =IF(Sheet1!S10="","",Sheet1!S10) | H10: =IF(Table1[[#This Row],[PrimaryEmail]]<>"","Yes","") -> Yes
B11: =Sheet1!D11 -> 19-000060 | C11: =Sheet1!B11 -> Luke Thomas | D11: =Sheet1!A11 -> Bennett | F11: =Sheet1!M11 -> courtneythomasou91@gmail.com | G11: =IF(Sheet1!S11="","",Sheet1!S11) | H11: =IF(Table1[[#This Row],[PrimaryEmail]]<>"","Yes","") -> Yes
B12: =Sheet1!D12 -> 15-002046 | C12: =Sheet1!B12 -> Anthony Michael | D12: =Sheet1!A12 -> Davidson | F12: =Sheet1!M12 -> mdavidson7@austin.rr.com | G12: =IF(Sheet1!S12="","",Sheet1!S12) | H12: =IF(Table1[[#This Row],[PrimaryEmail]]<>"","Yes","") -> Yes
B13: =Sheet1!D34 -> 12-000189 | C13: =Sheet1!B34 -> Michael Todd | D13: =Sheet1!A34 -> Dodson | F13: =Sheet1!M34 -> lismooring@aol.com | G13: =IF(Sheet1!S34="","",Sheet1!S34) -> danieldavidson879@gmail.com | H13: =IF(Table1[[#This Row],[PrimaryEmail]]<>"","Yes","") -> Yes
B14: =Sheet1!D14 -> 08-088136 | C14: =Sheet1!B14 -> Alexandra | D14: =Sheet1!A14 -> Hall | F14: =Sheet1!M14 | G14: =IF(Sheet1!S14="","",Sheet1!S14) | H14: =IF(Table1[[#This Row],[PrimaryEmail]]<>"","Yes","") -> Yes
B15: =Sheet1!D15 -> 24-001242 | C15: =Sheet1!B15 -> Ryan | D15: =Sheet1!A15 -> Jain | F15: =Sheet1!M15 -> meenu.jain@gmail.com | G15: =IF(Sheet1!S15="","",Sheet1!S15) -> ankur.ankurjain@gmail.com | H15: =IF(Table1[[#This Row],[PrimaryEmail]]<>"","Yes","") -> Yes
B16: =Sheet1!D16 -> 09-000016 | C16: =Sheet1!B16 -> Mary K. | D16: =Sheet1!A16 -> Loy | F16: =Sheet1!M16 -> melyssaloy@mac.com | G16: =IF(Sheet1!S16="","",Sheet1!S16) | H16: =IF(Table1[[#This Row],[PrimaryEmail]]<>"","Yes","") -> Yes
B17: =Sheet1!D17 -> 22-000706 | C17: =Sheet1!B17 -> Ryan Matthew | D17: =Sheet1!A17 -> Taylor | F17: =Sheet1!M17 -> 0 | G17: =IF(Sheet1!S17="","",Sheet1!S17) -> nktaylor76@gmail.com | H17: =IF(Table1[[#This Row],[PrimaryEmail]]<>"","Yes","") -> Yes
B18: =Sheet1!D18 -> 00-074302 | C18: =Sheet1!B18 -> Elizabeth | D18: =Sheet1!A18 -> Turnbaugh | F18: =Sheet1!M18 -> 0 | G18: =IF(Sheet1!S18="","",Sheet1!S18) | H18: =IF(Table1[[#This Row],[PrimaryEmail]]<>"","Yes","") -> Yes
B19: =Sheet1!D19 -> 23-000357 | C19: =Sheet1!B19 -> David Patrick | D19: =Sheet1!A19 -> Warren | F19: =Sheet1!M19 -> 0 | G19: =IF(Sheet1!S19="","",Sheet1!S19) -> juliepowellwarren@gmail.com | H19: =IF(Table1[[#This Row],[PrimaryEmail]]<>"","Yes","") -> Yes
B20: =Sheet1!D20 -> 05-82942 | C20: =Sheet1!B20 -> Oscar | D20: =Sheet1!A20 -> Luna | F20: =Sheet1!M20 -> medelc64@gmail.com | G20: =IF(Sheet1!S20="","",Sheet1!S20) | H20: =IF(Table1[[#This Row],[PrimaryEmail]]<>"","Yes","") -> Yes
B21: =Sheet1!D21 -> 06-085777 | C21: =Sheet1!B21 -> Benjamin | D21: =Sheet1!A21 -> Brener | F21: =Sheet1!M21 -> brefaye@hotmail.com | G21: =IF(Sheet1!S21="","",Sheet1!S21) -> lazarbre@hotmail.com | H21: =IF(Table1[[#This Row],[PrimaryEmail]]<>"","Yes","") -> Yes
B22: =Sheet1!D22 -> 09-001594 | C22: =Sheet1!B22 -> Mark | D22: =Sheet1!A22 -> Potter | F22: =Sheet1!M22 -> cjohnson@familyeldercare.org | G22: =IF(Sheet1!S22="","",Sheet1!S22) | H22: =IF(Table1[[#This Row],[PrimaryEmail]]<>"","Yes","") -> Yes
B23: =Sheet1!D23 -> 14-000172 | C23: =Sheet1!B23 -> Quinn | D23: =Sheet1!A23 -> Reich | F23: =Sheet1!M23 -> lleboeuf0807@gmail.com | G23: =IF(Sheet1!S23="","",Sheet1!S23) | H23: =IF(Table1[[#This Row],[PrimaryEmail]]<>"","Yes","") -> Yes
B24: =Sheet1!D24 -> 15-000428 | C24: =Sheet1!B24 -> Ty | D24: =Sheet1!A24 -> Cox | F24: =Sheet1!M24 -> mattjoncox@gmail.com | G24: =IF(Sheet1!S24="","",Sheet1!S24) -> amykcox1964@gmail.com | H24: =IF(Table1[[#This Row],[PrimaryEmail]]<>"","Yes","") -> Yes
B25: =Sheet1!D25 -> 17-000201 | C25: =Sheet1!B25 -> Jay | D25: =Sheet1!A25 -> Roberts | F25: =Sheet1!M25 -> streboryaj@gmail.com | G25: =IF(Sheet1!S25="","",Sheet1!S25) -> strebornelle@gmail.com | H25: =IF(Table1[[#This Row],[PrimaryEmail]]<>"","Yes","") -> Yes
... B33: =Sheet1!D33 -> 22-002744 | C33: =Sheet1!B33 -> Aidan | D33: =Sheet1!A33 -> Zarola | F33: =Sheet1!M33 -> thezarolas@gmail.com | G33: =IF(Sheet1!S33="","",Sheet1!S33) -> none | H33: =IF(Table1[[#This Row],[PrimaryEmail]]<>"","Yes","") -> Yes
B34: =Sheet1!#REF! -> #REF! | C34: =Sheet1!#REF! -> #REF! | D34: =Sheet1!#REF! -> #REF! | E34: A | F34: =Sheet1!#REF! -> #REF! | G34: =IF(Sheet1!#REF!="","",Sheet1!#REF!) -> #REF! | H34: =IF(Table1[[#This Row],[PrimaryEmail]]<>"","Yes","") -> #REF!
B35: =Sheet1!D35 -> 0 | C35: =Sheet1!B35 -> 0 | D35: =Sheet1!A35 -> 0 | E35: A | F35: =Sheet1!M35 -> 0 | G35: =IF(Sheet1!S35="","",Sheet1!S35) | H35: =IF(Table1[[#This Row],[PrimaryEmail]]<>"","Yes","") -> Yes
B36: =Sheet1!D36 -> 0 | C36: =Sheet1!B36 -> 0 | D36: =Sheet1!A36 -> 0 | E36: A | F36: =Sheet1!M36 -> 0 | G36: =IF(Sheet1!S36="","",Sheet1!S36) | H36: =IF(Table1[[#This Row],[PrimaryEmail]]<>"","Yes","") -> Yes
B37: =Sheet1!D37 -> 0 | C37: =Sheet1!B37 -> 0 | D37: =Sheet1!A37 -> 0 | E37: A | F37: =Sheet1!M37 -> 0 | G37: =IF(Sheet1!S37="","",Sheet1!S37) | H37: =IF(Table1[[#This Row],[PrimaryEmail]]<>"","Yes","") -> Yes
B38: =Sheet1!D38 -> 0 | C38: =Sheet1!B38 -> 0 | D38: =Sheet1!A38 -> 0 | E38: A | F38: =Sheet1!M38 -> 0 | G38: =IF(Sheet1!S38="","",Sheet1!S38) | H38: =IF(Table1[[#This Row],[PrimaryEmail]]<>"","Yes","") -> Yes
B39: =Sheet1!D39 -> 0 | C39: =Sheet1!B39 -> 0 | D39: =Sheet1!A39 -> 0 | E39: A | F39: =Sheet1!M39 -> 0 | G39: =IF(Sheet1!S39="","",Sheet1!S39) | H39: =IF(Table1[[#This Row],[PrimaryEmail]]<>"","Yes","") -> Yes
B40: =Sheet1!D40 -> 0 | C40: =Sheet1!B40 -> 0 | D40: =Sheet1!A40 -> 0 | E40: A | F40: =Sheet1!M40 -> 0 | G40: =IF(Sheet1!S40="","",Sheet1!S40) | H40: =IF(Table1[[#This Row],[PrimaryEmail]]<>"","Yes","") -> Yes
B41: =Sheet1!D41 -> 0 | C41: =Sheet1!B41 -> 0 | D41: =Sheet1!A41 -> 0 | E41: A | F41: =Sheet1!M41 -> 0 | G41: =IF(Sheet1!S41="","",Sheet1!S41) | H41: =IF(Table1[[#This Row],[PrimaryEmail]]<>"","Yes","") -> Yes
B42: =Sheet1!D42 -> 0 | C42: =Sheet1!B42 -> 0 | D42: =Sheet1!A42 -> 0 | E42: A | F42: =Sheet1!M42 -> 0 | G42: =IF(Sheet1!S42="","",Sheet1!S42) | H42: =IF(Table1[[#This Row],[PrimaryEmail]]<>"","Yes","") -> Yes
B43: =Sheet1!D43 -> 0 | C43: =Sheet1!B43 -> 0 | D43: =Sheet1!A43 -> 0 | E43: A | F43: =Sheet1!M43 -> 0 | G43: =IF(Sheet1!S43="","",Sheet1!S43) | H43: =IF(Table1[[#This Row],[PrimaryEmail]]<>"","Yes","") -> Yes
B44: =Sheet1!D44 -> 0 | C44: =Sheet1!B44 -> 0 | D44: =Sheet1!A44 -> 0 | E44: A | F44: =Sheet1!M44 -> 0 | G44: =IF(Sheet1!S44="","",Sheet1!S44) | H44: =IF(Table1[[#This Row],[PrimaryEmail]]<>"","Yes","") -> Yes
B45: =Sheet1!D45 -> 0 | C45: =Sheet1!B45 -> 0 | D45: =Sheet1!A45 -> 0 | E45: A | F45: =Sheet1!M45 -> 0 | G45: =IF(Sheet1!S45="","",Sheet1!S45) | H45: =IF(Table1[[#This Row],[PrimaryEmail]]<>"","Yes","") -> Yes
B46: =Sheet1!D46 -> 0 | C46: =Sheet1!B46 -> 0 | D46: =Sheet1!A46 -> 0 | E46: A | F46: =Sheet1!M46 -> 0 | G46: =IF(Sheet1!S46="","",Sheet1!S46) | H46: =IF(Table1[[#This Row],[PrimaryEmail]]<>"","Yes","") -> Yes
... B1000: =Sheet1!D1000 -> 0 | C1000: =Sheet1!B1000 -> 0 | D1000: =Sheet1!A1000 -> 0 | E1000: A | F1000: =Sheet1!M1000 -> 0 | G1000: =IF(Sheet1!S1000="","",Sheet1!S1000) | H1000: =IF(Table1[[#This Row],[PrimaryEmail]]<>"","Yes","") -> Yes

Sheet Contacts
A1: ContactID | B1: DisplayName | C1: EmailPrimary | D1: EmailAlt | E1: Phone | F1: Org | G1: RoleType | H1: ConsentToEmail | I1: Notes

Sheet ClientContacts
A1: ClientID | B1: ContactID | C1: Relationship | D1: IsPrimary

Sheet Messages
A1: LogID | B1: ClientID | C1: CauseNo | D1: Timestamp | E1: Provider | F1: GmailMessageId | G1: GmailThreadId | H1: ThreadURL | I1: From | J1: To | K1: CC | L1: Subject | M1: Snippet | N1: BodyPreview | O1: HasAttachments | P1: TemplateID | Q1: TemplateVersion | R1: Module | S1: Direction | T1: Status | U1: ErrorNote
A2: e168efc0-d51b-4b07-9306-a8c320cf0bc2 | C2: 21-001411 | D2: 2025-10-15T09:24:24 | E2: gmail | I2: yourname@gmail.com | J2: txgirl14boys@gmail.com | L2: Friendly Reminder | M2: Hello there, This is a friendly reminder about your upcoming item for John Carter Wagner (Cause #21-001411). If you have questions, reply to this email. Thank you, Cour | O2: N | P2: simple_reminder | Q2: 1.0.0 | R2: Email | S2: OUTBOUND | T2: PREVIEW
A3: 6e3370df-22dc-4647-ba8a-4870cd35104c | C3: 17-000729 | D3: 2025-10-15T09:24:28 | E3: gmail | I3: yourname@gmail.com | J3: ljdenis214@gmail.com | L3: Friendly Reminder | M3: Hello there, This is a friendly reminder about your upcoming item for Abigail Dennis (Cause #17-000729). If you have questions, reply to this email. Thank you, Court Vis | O3: N | P3: simple_reminder | Q3: 1.0.0 | R3: Email | S3: OUTBOUND | T3: PREVIEW
A4: 5e9d9125-a05e-4183-addc-8c286c60eab4 | C4: 22-001301 | D4: 2025-10-15T09:24:34 | E4: gmail | I4: yourname@gmail.com | J4: amyhalford710@gmail.com | L4: Friendly Reminder | M4: Hello there, This is a friendly reminder about your upcoming item for Jon Tyler Halford (Cause #22-001301). If you have questions, reply to this email. Thank you, Court | O4: N | P4: simple_reminder | Q4: 1.0.0 | R4: Email | S4: OUTBOUND | T4: PREVIEW
A5: 1a1bc251-4c10-4efc-a649-93deda2ad6a9 | C5: 22-002249 | D5: 2025-10-15T09:24:40 | E5: gmail | I5: yourname@gmail.com | J5: lina@mircareconsultants.com | L5: Friendly Reminder | M5: Hello there, This is a friendly reminder about your upcoming item for Daniel Braden (Cause #22-002249). If you have questions, reply to this email. Thank you, Court Vis | O5: N | P5: simple_reminder | Q5: 1.0.0 | R5: Email | S5: OUTBOUND | T5: PREVIEW
A6: 7546fba4-de1b-4037-a1a4-3eeef1bd00cc | C6: 16-000206 | D6: 2025-10-15T09:24:46 | E6: gmail | I6: yourname@gmail.com | J6: valmayerik@gmail.com | L6: Friendly Reminder | M6: Hello there, This is a friendly reminder about your upcoming item for Julian Mayerik Conner (Cause #16-000206). If you have questions, reply to this email. Thank you, C | O6: N | P6: simple_reminder | Q6: 1.0.0 | R6: Email | S6: OUTBOUND | T6: PREVIEW
A7: d868a9c7-ae38-46fc-bc9d-1201607715aa | C7: 14-002049 | D7: 2025-10-15T09:24:51 | E7: gmail | I7: yourname@gmail.com | J7: kedejong@msn.com | L7: Friendly Reminder | M7: Hello there, This is a friendly reminder about your upcoming item for Brendan James De Jong (Cause #14-002049). If you have questions, reply to this email. Thank you, Co | O7: N | P7: simple_reminder | Q7: 1.0.0 | R7: Email | S7: OUTBOUND | T7: PREVIEW
A8: 10b3e290-0e95-4771-930f-b475121db552 | C8: 06-084450 | D8: 2025-10-15T09:25:06 | E8: gmail | I8: yourname@gmail.com | J8: braden ca | L8: Friendly Reminder | M8: Hello there, This is a friendly reminder about your upcoming item for Kimberly Grace Eudy (Cause #06-084450). If you have questions, reply to this email. Thank you, Cour | O8: N | P8: simple_reminder | Q8: 1.0.0 | R8: Email | S8: OUTBOUND | T8: PREVIEW
A9: bc1e6de9-72b7-4caa-ae38-e0ab6afb3494 | C9: 20-001710 | D9: 2025-10-15T09:25:12 | E9: gmail | I9: yourname@gmail.com | J9: apjon1@yahoo.com | L9: Friendly Reminder | M9: Hello there, This is a friendly reminder about your upcoming item for Andrew Colton Jones (Cause #20-001710). If you have questions, reply to this email. Thank you, Cour | O9: N | P9: simple_reminder | Q9: 1.0.0 | R9: Email | S9: OUTBOUND | T9: PREVIEW
A10: ce1cbe32-4b32-4894-8541-d725acc65dc7 | C10: 18-001798 | D10: 2025-10-15T09:25:16 | E10: gmail | I10: yourname@gmail.com | J10: randalpark@yahoo.com | L10: Friendly Reminder | M10: Hello there, This is a friendly reminder about your upcoming item for Mina Park (Cause #18-001798). If you have questions, reply to this email. Thank you, Court Visitor | O10: N | P10: simple_reminder | Q10: 1.0.0 | R10: Email | S10: OUTBOUND | T10: PREVIEW
A11: 5d8eca48-09ac-4ca3-83eb-b39e717ef312 | C11: 19-000060 | D11: 2025-10-15T09:25:22 | E11: gmail | I11: yourname@gmail.com | J11: courtneythomasou91@gmail.com | L11: Friendly Reminder | M11: Hello there, This is a friendly reminder about your upcoming item for Luke Thomas Bennett (Cause #19-000060). If you have questions, reply to this email. Thank you, Cou | O11: N | P11: simple_reminder | Q11: 1.0.0 | R11: Email | S11: OUTBOUND | T11: PREVIEW
A12: 7da1b910-478d-432c-9286-91706a478c08 | C12: 15-002046 | D12: 2025-10-15T09:25:29 | E12: gmail | I12: yourname@gmail.com | J12: mdavidson7@austin.rr.com | L12: Friendly Reminder | M12: Hello there, This is a friendly reminder about your upcoming item for Anthony Michael Davidson (Cause #15-002046). If you have questions, reply to this email. Thank you, | O12: N | P12: simple_reminder | Q12: 1.0.0 | R12: Email | S12: OUTBOUND | T12: PREVIEW
A13: 7ffcf17c-f99c-4071-9f5f-673a0d1db596 | C13: 12-000189 | D13: 2025-10-15T09:25:34 | E13: gmail | I13: yourname@gmail.com | J13: lismooring@aol.com | K13: danieldavidson879@gmail.com | L13: Friendly Reminder | M13: Hello there, This is a friendly reminder about your upcoming item for Michael Todd Dodson (Cause #12-000189). If you have questions, reply to this email. Thank you, Cour | O13: N | P13: simple_reminder | Q13: 1.0.0 | R13: Email | S13: OUTBOUND | T13: PREVIEW
A14: 8a690335-fc9d-4876-89cf-dc403d9d4939 | C14: 24-001242 | D14: 2025-10-15T09:25:41 | E14: gmail | I14: yourname@gmail.com | J14: meenu.jain@gmail.com | K14: ankur.ankurjain@gmail.com | L14: Friendly Reminder | M14: Hello there, This is a friendly reminder about your upcoming item for Ryan Jain (Cause #24-001242). If you have questions, reply to this email. Thank you, Court Visitor | O14: N | P14: simple_reminder | Q14: 1.0.0 | R14: Email | S14: OUTBOUND | T14: PREVIEW
A15: 0bc61be1-a139-4817-9955-8bfcdc36bf4c | C15: 09-000016 | D15: 2025-10-15T09:25:48 | E15: gmail | I15: yourname@gmail.com | J15: melyssaloy@mac.com | L15: Friendly Reminder | M15: Hello there, This is a friendly reminder about your upcoming item for Mary K. Loy (Cause #09-000016). If you have questions, reply to this email. Thank you, Court Visito | O15: N | P15: simple_reminder | Q15: 1.0.0 | R15: Email | S15: OUTBOUND | T15: PREVIEW
A16: fb5a4f08-2610-4668-a8b5-f644d18b74a2 | C16: 05-82942 | D16: 2025-10-15T09:25:55 | E16: gmail | I16: yourname@gmail.com | J16: medelc64@gmail.com | L16: Friendly Reminder | M16: Hello there, This is a friendly reminder about your upcoming item for Oscar Luna (Cause #05-82942). If you have questions, reply to this email. Thank you, Court Visitor | O16: N | P16: simple_reminder | Q16: 1.0.0 | R16: Email | S16: OUTBOUND | T16: PREVIEW
A17: 9ade24ab-75f3-414b-a92d-9f05813813fd | C17: 06-085777 | D17: 2025-10-15T09:26:04 | E17: gmail | I17: yourname@gmail.com | J17: brefaye@hotmail.com | K17: lazarbre@hotmail.com | L17: Friendly Reminder | M17: Hello there, This is a friendly reminder about your upcoming item for Benjamin Brener (Cause #06-085777). If you have questions, reply to this email. Thank you, Court Vi | O17: N | P17: simple_reminder | Q17: 1.0.0 | R17: Email | S17: OUTBOUND | T17: PREVIEW
A18: 607cdc2b-6895-43d6-bbc1-c05da6e095b6 | C18: 09-001594 | D18: 2025-10-15T09:26:07 | E18: gmail | I18: yourname@gmail.com | J18: cjohnson@familyeldercare.org | L18: Friendly Reminder | M18: Hello there, This is a friendly reminder about your upcoming item for Mark Potter (Cause #09-001594). If you have questions, reply to this email. Thank you, Court Visito | O18: N | P18: simple_reminder | Q18: 1.0.0 | R18: Email | S18: OUTBOUND | T18: PREVIEW
A19: b8fa8ed3-880a-41de-8b70-5fc75d589834 | C19: 14-000172 | D19: 2025-10-15T09:26:15 | E19: gmail | I19: yourname@gmail.com | J19: lleboeuf0807@gmail.com | L19: Friendly Reminder | M19: Hello there, This is a friendly reminder about your upcoming item for Quinn Reich (Cause #14-000172). If you have questions, reply to this email. Thank you, Court Visito | O19: N | P19: simple_reminder | Q19: 1.0.0 | R19: Email | S19: OUTBOUND | T19: PREVIEW
A20: 8fdfc5e3-c41d-4a80-a729-d1f74ab4b0bd | C20: 15-000428 | D20: 2025-10-15T09:26:20 | E20: gmail | I20: yourname@gmail.com | J20: mattjoncox@gmail.com | K20: amykcox1964@gmail.com | L20: Friendly Reminder | M20: Hello there, This is a friendly reminder about your upcoming item for Ty Cox (Cause #15-000428). If you have questions, reply to this email. Thank you, Court Visitor | O20: N | P20: simple_reminder | Q20: 1.0.0 | R20: Email | S20: OUTBOUND | T20: PREVIEW
A21: 723b18a7-5cd5-4137-92e3-fffd6b0d1434 | C21: 17-000201 | D21: 2025-10-15T09:26:26 | E21: gmail | I21: yourname@gmail.com | J21: streboryaj@gmail.com | K21: strebornelle@gmail.com | L21: Friendly Reminder | M21: Hello there, This is a friendly reminder about your upcoming item for Jay Roberts (Cause #17-000201). If you have questions, reply to this email. Thank you, Court Visito | O21: N | P21: simple_reminder | Q21: 1.0.0 | R21: Email | S21: OUTBOUND | T21: PREVIEW
A22: 6e8d200f-2cc1-4d27-ad0d-a6c2f511b114 | C22: 18-000194 | D22: 2025-10-15T09:26:34 | E22: gmail | I22: yourname@gmail.com | J22: datoney2@gmail.com | L22: Friendly Reminder | M22: Hello there, This is a friendly reminder about your upcoming item for Emma Toney (Cause #18-000194). If you have questions, reply to this email. Thank you, Court Visitor | O22: N | P22: simple_reminder | Q22: 1.0.0 | R22: Email | S22: OUTBOUND | T22: PREVIEW
A23: 84e26700-6fee-4093-941b-8473282f398b | C23: 99-071988 | D23: 2025-10-15T09:26:40 | E23: gmail | I23: yourname@gmail.com | J23: rlontkowski@familyeldercare.org | L23: Friendly Reminder | M23: Hello there, This is a friendly reminder about your upcoming item for Jose Ximenez (Cause #99-071988). If you have questions, reply to this email. Thank you, Court Visit | O23: N | P23: simple_reminder | Q23: 1.0.0 | R23: Email | S23: OUTBOUND | T23: PREVIEW
A24: 5ac79097-2d31-40ce-ae24-562545d383d4 | C24: 05-082943 | D24: 2025-10-15T09:26:46 | E24: gmail | I24: yourname@gmail.com | J24: magda.wolk@gmail.com | L24: Friendly Reminder | M24: Hello there, This is a friendly reminder about your upcoming item for James Wolk (Cause #05-082943). If you have questions, reply to this email. Thank you, Court Visitor | O24: N | P24: simple_reminder | Q24: 1.0.0 | R24: Email | S24: OUTBOUND | T24: PREVIEW
A25: 0f795184-b261-4873-860f-b5644d99b2a3 | C25: 13-000934 | D25: 2025-10-15T09:26:53 | E25: gmail | I25: yourname@gmail.com | J25: wendyjimmerson@gmail.com | L25: Friendly Reminder | M25: Hello there, This is a friendly reminder about your upcoming item for Abby Jimmerson (Cause #13-000934). If you have questions, reply to this email. Thank you, Court Vis | O25: N | P25: simple_reminder | Q25: 1.0.0 | R25: Email | S25: OUTBOUND | T25: PREVIEW
A26: 117715dc-aa87-46d2-a3f0-3a9d71e025b3 | C26: 19-000694 | D26: 2025-10-15T09:26:58 | E26: gmail | I26: yourname@gmail.com | J26: tpcaglejr@gmail.com | K26: none | L26: Friendly Reminder | M26: Hello there, This is a friendly reminder about your upcoming item for Sara Cagle (Cause #19-000694). If you have questions, reply to this email. Thank you, Court Visitor | O26: N | P26: simple_reminder | Q26: 1.0.0 | R26: Email | S26: OUTBOUND | T26: PREVIEW
A27: 67389d53-3c85-4778-a883-c538872f318b | C27: 21-000066 | D27: 2025-10-15T09:27:04 | E27: gmail | I27: yourname@gmail.com | J27: JeM0801@gmail.com | K27: none | L27: Friendly Reminder | M27: Hello there, This is a friendly reminder about your upcoming item for Mason Mogonye (Cause #21-000066). If you have questions, reply to this email. Thank you, Court Visi | O27: N | P27: simple_reminder | Q27: 1.0.0 | R27: Email | S27: OUTBOUND | T27: PREVIEW
A28: cc779035-bdc4-469a-89a5-cff2b2404f48 | C28: 22-002744 | D28: 2025-10-15T09:27:18 | E28: gmail | I28: yourname@gmail.com | J28: thezarolas@gmail.com | K28: none | L28: Friendly Reminder | M28: Hello there, This is a friendly reminder about your upcoming item for Aidan Zarola (Cause #22-002744). If you have questions, reply to this email. Thank you, Court Visit | O28: N | P28: simple_reminder | Q28: 1.0.0 | R28: Email | S28: OUTBOUND | T28: PREVIEW
A29: b5b01524-6466-43d2-bc30-a0588909d924 | C29: 22-195700 | D29: 2025-10-15T09:27:31 | E29: gmail | I29: yourname@gmail.com | J29: mayehres@gmail.com | L29: Friendly Reminder | M29: Hello there, This is a friendly reminder about your upcoming item for susan ehresman (Cause #22-195700). If you have questions, reply to this email. Thank you, Court Vis | O29: N | P29: simple_reminder | Q29: 1.0.0 | R29: Email | S29: OUTBOUND | T29: PREVIEW

Sheet MessageRecipients
A1: LogID | B1: ContactID | C1: Type
A2: e168efc0-d51b-4b07-9306-a8c320cf0bc2 | C2: TO
A3: 6e3370df-22dc-4647-ba8a-4870cd35104c | C3: TO
A4: 5e9d9125-a05e-4183-addc-8c286c60eab4 | C4: TO
A5: 1a1bc251-4c10-4efc-a649-93deda2ad6a9 | C5: TO
A6: 7546fba4-de1b-4037-a1a4-3eeef1bd00cc | C6: TO
A7: d868a9c7-ae38-46fc-bc9d-1201607715aa | C7: TO
A8: 10b3e290-0e95-4771-930f-b475121db552 | C8: TO
A9: bc1e6de9-72b7-4caa-ae38-e0ab6afb3494 | C9: TO
A10: ce1cbe32-4b32-4894-8541-d725acc65dc7 | C10: TO
A11: 5d8eca48-09ac-4ca3-83eb-b39e717ef312 | C11: TO
A12: 7da1b910-478d-432c-9286-91706a478c08 | C12: TO
A13: 7ffcf17c-f99c-4071-9f5f-673a0d1db596 | C13: TO
... A37: b5b01524-6466-43d2-bc30-a0588909d924 | C37: TO

Sheet MessageLinks
A1: LogID | B1: ClientID
A2: e168efc0-d51b-4b07-9306-a8c320cf0bc2
A3: 6e3370df-22dc-4647-ba8a-4870cd35104c
A4: 5e9d9125-a05e-4183-addc-8c286c60eab4
A5: 1a1bc251-4c10-4efc-a649-93deda2ad6a9
A6: 7546fba4-de1b-4037-a1a4-3eeef1bd00cc
A7: d868a9c7-ae38-46fc-bc9d-1201607715aa
A8: 10b3e290-0e95-4771-930f-b475121db552
A9: bc1e6de9-72b7-4caa-ae38-e0ab6afb3494
A10: ce1cbe32-4b32-4894-8541-d725acc65dc7
A11: 5d8eca48-09ac-4ca3-83eb-b39e717ef312
A12: 7da1b910-478d-432c-9286-91706a478c08
A13: 7ffcf17c-f99c-4071-9f5f-673a0d1db596
... A29: b5b01524-6466-43d2-bc30-a0588909d924

Sheet TemplatesIndex
A1: TemplateID | B1: Version | C1: Purpose | D1: SubjectDefault | E1: FilePath
A2: simple_reminder | B2: 1.0.0 | C2: General gentle reminder | D2: Friendly Reminder | E2: C:\GoogleSync\Guardianship Files\data files\Emails\templates\simple_reminder.html
