Workbook

Sheet Sheet1
A1: wardlast | B1: wardfirst | C1: wardmiddle | D1: causeno | E1: visitdate | F1: visittime | G1: wtele | H1: liveswith | I1: waddress | J1: wdob | K1: guardian1 | L1: gaddress | M1: gemail | N1: gtele | O1: Relationship | P1: gdob | Q1: Guardian2 | R1: g2 address | S1: g2eamail | T1: g2tele | U1: g2Relationship | V1: g2dob | W1: datesubmitted | X1: Dateappointed | Y1: miles | Z1: expense submitted | AA1: expensepd | AB1: DateARPfiled | AC1: Comments | AD1: CVR created? | AE1: emailsent | AF1: Appt_confirmed | AG1: Contact_added
A2: Luna | B2: Oscar | D2: 05-082942 | G2: (512) 282-1208 | I2: 2406 Monarch Dr., Austin, TX. 7874.8 | J2: 31916 | K2: Catalina Medel | L2: 2406 Monarch Dr., Austin, TX. 7874.8 | M2: Medelc64@gmail.com | N2: (512) 282-1208 | O2: Mother | P2: 23486 | X2: 45833
A3: Cas | B3: Cos | C3: Cos | D3: 06-085777 | I3: 2404 Roehampton Dr., Austin, TX | J3: 32518 | K3: Fay Brener | L3: 2404 Roehampton Dr., Austin, TX | M3: lazarbre@hotmail.com | P3: 20843 | X3: 45896
A4: Jaimes | B4: Jayleen | D4: 09-001594 | G4: (512) 789-4079 | I4: Austin, Texas 78745 | J4: 20160 | K4: Family Eldercare | L4: Austin, Texas 78745 | M4: cjohnson@familyeldercare.org_ | N4: (512) 628-1693 | O4: Public Guardian | Q4: Inc. - Christi Johnson | R4: Austin, Texas 78745 | X4: 45897 | AB4: 45747
A5: Reich | B5: Quinn | C5: Leboeuf | D5: 14-000172 | G5: (512) 517-5680 | I5: 6008 Rutledge Ln, Austin. Tx 78745 | J5: 35094 | L5: 6008 Rutledge Ln, Austin. Tx 78745 | M5: leboeuf0807@gmail.com | N5: (512) 517-5680 | O5: Parent | P5: 22865 | T5: (512) 306-7314 | X5: 45897 | AB5: 45821
A6: Cox | B6: Ty | D6: 15-000428 | I6: 4415 Hoffman Dr, 2. GUARDIAN(s): Name(s) Matthew & Amy Cox | J6: 33381 | K6: Matthew Cox | L6: 4415 Hoffman Dr | M6: amykcox1944@gmail.com | O6: Father/Mother | Q6: Amy Cox | R6: 4415 Hoffman Dr | X6: 45897
A7: Roberts | B7: Jay | C7: Daniel | D7: 17-000201 | G7: (512) 560-2265 | I7: 6452 Ruxton Ln, Austin TX. 78749 | J7: 36216 | K7: Jay R Roberts | L7: 6452 Ruxton Ln, Austin TX. 78749 | M7: strebornelle@gmail.com | N7: (512) 417-2350 | O7: Father/Mother | P7: 24667 | Q7: Ellen M Roberts | R7: 6452 Ruxton Ln, Austin TX. 78749 | T7: (512) 560-2265 | X7: 45896 | AB7: 45726
A8: Toney | B8: A | C8: Jaye | D8: 18-000194 | I8: DRIFTWOOD 78619 | K8: Derrick A Toney | L8: DRIFTWOOD 78619 | O8: Mother | X8: 45897
A9: Huerta | B9: Gabriela | C9: Esperanza | D9: 19-002069 | G9: (512) 497-3944 | I9: 8800 Ravello Pass, Austin, TX 78749 | J9: 37074 | K9: Gabriela Esperanza Huerta | L9: 8800 Ravello Pass, Austin, TX 78749 | N9: (512) 497-3944 | O9: Father/Mother | T9: (512) 826-1616 | X9: 45896
A10: Limon-mercado | B10: Dyana | D10: 99-071988 | G10: (512) 448-9559 | I10: 2517 Mc Gregor Dr, Austin, TX 78745 | J10: 29809 | K10: Family Eldercare | L10: 2517 Mc Gregor Dr, Austin, TX 78745 | M10: rlontkowski@familyeldercare.org | N10: (512) 483-3564 | O10: Public Guardian | Q10: Inc. - Robert Lontkowski | R10: 2517 Mc Gregor Dr, Austin, TX 78745 | X10: 45897 | AB10: 45740

Sheet Sheet2
A1: causeno | B1: dateappointed | C1: visitdate | D1: datesubmitted | G1: directions | I1: name
A2: =Sheet1!#REF! -> #REF! | B2: =Sheet1!#REF! -> #REF! | C2: =Sheet1!#REF! -> #REF! | D2: =Sheet1!#REF! -> #REF! | G2: =HYPERLINK("https://www.google.com/maps/dir//''/data=!4m7?q="&J2,"Get Directions") -> #REF! | I2: =Sheet1!#REF! -> #REF! | J2: =Sheet1!#REF! -> #REF!
A3: =Sheet1!#REF! -> #REF! | B3: =Sheet1!#REF! -> #REF! | C3: =Sheet1!#REF! -> #REF! | D3: =Sheet1!#REF! -> #REF! | G3: =HYPERLINK("https://www.google.com/maps/dir/Current+Location/"&J3,"Get Directions") -> #REF! | I3: =Sheet1!#REF! -> #REF! | J3: =Sheet1!#REF! -> #REF!
A4: =Sheet1!#REF! -> #REF! | B4: =Sheet1!#REF! -> #REF! | C4: =Sheet1!#REF! -> #REF! | D4: =Sheet1!#REF! -> #REF! | G4: =HYPERLINK("https://www.google.com/maps/dir/Current+Location/"&J4,"Get Directions") -> #REF! | I4: =Sheet1!#REF! -> #REF! | J4: =Sheet1!#REF! -> #REF!
A5: =Sheet1!#REF! -> #REF! | B5: =Sheet1!#REF! -> #REF! | C5: =Sheet1!#REF! -> #REF! | D5: =Sheet1!#REF! -> #REF! | G5: =HYPERLINK("https://www.google.com/maps/dir/Current+Location/"&J5,"Get Directions") -> #REF! | I5: =Sheet1!#REF! -> #REF! | J5: =Sheet1!#REF! -> #REF!
A6: =Sheet1!#REF! -> #REF! | B6: =Sheet1!#REF! -> #REF! | C6: =Sheet1!#REF! -> #REF! | D6: =Sheet1!#REF! -> #REF! | G6: =HYPERLINK("https://www.google.com/maps/dir/Current+Location/"&J6,"Get Directions") -> #REF! | I6: =Sheet1!#REF! -> #REF! | J6: =Sheet1!#REF! -> #REF!
A7: =Sheet1!#REF! -> #REF! | B7: =Sheet1!#REF! -> #REF! | C7: =Sheet1!#REF! -> #REF! | D7: =Sheet1!#REF! -> #REF! | G7: =HYPERLINK("https://www.google.com/maps/dir/Current+Location/"&J7,"Get Directions") -> #REF! | I7: =Sheet1!#REF! -> #REF! | J7: =Sheet1!#REF! -> #REF!
A8: =Sheet1!#REF! -> #REF! | B8: =Sheet1!#REF! -> #REF! | C8: =Sheet1!#REF! -> #REF! | D8: =Sheet1!#REF! -> #REF! | G8: =HYPERLINK("https://www.google.com/maps/dir/Current+Location/"&J8,"Get Directions") -> #REF! | I8: =Sheet1!#REF! -> #REF! | J8: =Sheet1!#REF! -> #REF!
A9: =Sheet1!#REF! -> #REF! | B9: =Sheet1!#REF! -> #REF! | C9: =Sheet1!#REF! -> #REF! | D9: =Sheet1!#REF! -> #REF! | G9: =HYPERLINK("https://www.google.com/maps/dir/Current+Location/"&J9,"Get Directions") -> #REF! | I9: =Sheet1!#REF! -> #REF! | J9: =Sheet1!#REF! -> #REF!
A10: =Sheet1!#REF! -> #REF! | B10: =Sheet1!#REF! -> #REF! | C10: =Sheet1!#REF! -> #REF! | D10: =Sheet1!#REF! -> #REF! | G10: =HYPERLINK("https://www.google.com/maps/dir/Current+Location/"&J10,"Get Directions") -> #REF! | I10: =Sheet1!#REF! -> #REF! | J10: =Sheet1!#REF! -> #REF!
A11: =Sheet1!#REF! -> #REF! | B11: =Sheet1!#REF! -> #REF! | C11: =Sheet1!#REF! -> #REF! | D11: =Sheet1!#REF! -> #REF! | G11: =HYPERLINK("https://www.google.com/maps/dir/Current+Location/"&J11,"Get Directions") -> #REF! | I11: =Sheet1!#REF! -> #REF! | J11: =Sheet1!#REF! -> #REF!
A12: =Sheet1!#REF! -> #REF! | B12: =Sheet1!#REF! -> #REF! | C12: =Sheet1!#REF! -> #REF! | D12: =Sheet1!#REF! -> #REF! | G12: =HYPERLINK("https://www.google.com/maps/dir/Current+Location/"&J12,"Get Directions") -> #REF! | I12: =Sheet1!#REF! -> #REF! | J12: =Sheet1!#REF! -> #REF!
A13: =Sheet1!#REF! -> #REF! | B13: =Sheet1!#REF! -> #REF! | C13: =Sheet1!#REF! -> #REF! | D13: =Sheet1!#REF! -> #REF! | G13: =HYPERLINK("https://www.google.com/maps/dir/Current+Location/"&J13,"Get Directions") -> #REF! | I13: =Sheet1!#REF! -> #REF! | J13: =Sheet1!#REF! -> #REF!
A14: =Sheet1!#REF! -> #REF! | B14: =Sheet1!#REF! -> #REF! | C14: =Sheet1!#REF! -> #REF! | D14: =Sheet1!#REF! -> #REF! | G14: =HYPERLINK("https://www.google.com/maps/dir/Current+Location/"&J14,"Get Directions") -> #REF! | I14: =Sheet1!#REF! -> #REF! | J14: =Sheet1!#REF! -> #REF!
A15: =Sheet1!#REF! -> #REF! | B15: =Sheet1!#REF! -> #REF! | C15: =Sheet1!#REF! -> #REF! | D15: =Sheet1!#REF! -> #REF! | G15: =HYPERLINK("https://www.google.com/maps/dir/Current+Location/"&J15,"Get Directions") -> #REF! | I15: =Sheet1!#REF! -> #REF! | J15: =Sheet1!#REF! -> #REF!
A16: =Sheet1!#REF! -> #REF! | B16: =Sheet1!#REF! -> #REF! | C16: =Sheet1!#REF! -> #REF! | D16: 45897 | G16: =HYPERLINK("https://www.google.com/maps/dir/Current+Location/"&J16,"Get Directions") -> #REF! | I16: =Sheet1!#REF! -> #REF! | J16: =Sheet1!#REF! -> #REF!
A17: =Sheet1!#REF! -> #REF! | B17: =Sheet1!#REF! -> #REF! | C17: =Sheet1!#REF! -> #REF! | D17: =Sheet1!#REF! -> #REF! | G17: =HYPERLINK("https://www.google.com/maps/dir/Current+Location/"&J17,"Get Directions") -> #REF! | I17: =Sheet1!#REF! -> #REF! | J17: =Sheet1!#REF! -> #REF!
A18: =Sheet1!#REF! -> #REF! | B18: =Sheet1!#REF! -> #REF! | C18: =Sheet1!#REF! -> #REF! | D18: =Sheet1!#REF! -> #REF! | G18: =HYPERLINK("https://www.google.com/maps/dir/Current+Location/"&I18,"Get Directions") -> #REF! | I18: =Sheet1!#REF! -> #REF! | J18: =Sheet1!#REF! -> #REF!
A19: =Sheet1!#REF! -> #REF! | B19: =Sheet1!#REF! -> #REF! | C19: =Sheet1!#REF! -> #REF! | D19: 45897 | G19: =HYPERLINK("https://www.google.com/maps/dir/Current+Location/"&J19,"Get Directions") -> #REF! | I19: =Sheet1!#REF! -> #REF! | J19: =Sheet1!#REF! -> #REF!
A20: =Sheet1!#REF! -> #REF! | B20: =Sheet1!#REF! -> #REF! | C20: =Sheet1!#REF! -> #REF! | D20: =Sheet1!#REF! -> #REF! | G20: =HYPERLINK("https://www.google.com/maps/dir/Current+Location/"&J20,"Get Directions") -> #REF! | I20: =Sheet1!#REF! -> #REF! | J20: =Sheet1!#REF! -> #REF! | L20: Luna
A21: =Sheet1!#REF! -> #REF! | B21: =Sheet1!#REF! -> #REF! | C21: =Sheet1!#REF! -> #REF! | D21: =Sheet1!#REF! -> #REF! | I21: =Sheet1!#REF! -> #REF! | J21: =Sheet1!#REF! -> #REF! | L21: Brener
A22: =Sheet1!#REF! -> #REF! | B22: =Sheet1!#REF! -> #REF! | C22: =Sheet1!#REF! -> #REF! | D22: =Sheet1!#REF! -> #REF! | G22: =HYPERLINK("https://www.google.com/maps/dir/Current+Location/"&J22,"Get Directions") -> #REF! | I22: =Sheet1!#REF! -> #REF! | J22: =Sheet1!#REF! -> #REF! | L22: Potter
A23: =Sheet1!#REF! -> #REF! | B23: =Sheet1!#REF! -> #REF! | C23: =Sheet1!#REF! -> #REF! | D23: =Sheet1!#REF! -> #REF! | G23: =HYPERLINK("https://www.google.com/maps/dir/Current+Location/"&J23,"Get Directions") -> #REF! | I23: =Sheet1!#REF! -> #REF! | J23: =Sheet1!#REF! -> #REF! | L23: Reich
A24: =Sheet1!#REF! -> #REF! | B24: =Sheet1!#REF! -> #REF! | C24: =Sheet1!#REF! -> #REF! | D24: =Sheet1!#REF! -> #REF! | G24: =HYPERLINK("https://www.google.com/maps/dir/Current+Location/"&J24,"Get Directions") -> #REF! | I24: =Sheet1!#REF! -> #REF! | J24: =Sheet1!#REF! -> #REF! | L24: Cox
A25: =Sheet1!#REF! -> #REF! | B25: =Sheet1!#REF! -> #REF! | C25: =Sheet1!#REF! -> #REF! | D25: =Sheet1!#REF! -> #REF! | G25: =HYPERLINK("https://www.google.com/maps/dir/Current+Location/"&J25,"Get Directions") -> #REF! | I25: =Sheet1!#REF! -> #REF! | J25: =Sheet1!#REF! -> #REF! | L25: Roberts
A26: =Sheet1!#REF! -> #REF! | B26: =Sheet1!#REF! -> #REF! | C26: =Sheet1!#REF! -> #REF! | D26: =Sheet1!#REF! -> #REF! | G26: =HYPERLINK("https://www.google.com/maps/dir/Current+Location/"&J26,"Get Directions") -> #REF! | I26: =Sheet1!#REF! -> #REF! | J26: =Sheet1!#REF! -> #REF! | L26: Toney
A27: =Sheet1!#REF! -> #REF! | B27: =Sheet1!#REF! -> #REF! | C27: =Sheet1!#REF! -> #REF! | D27: =Sheet1!#REF! -> #REF! | G27: =HYPERLINK("https://www.google.com/maps/dir/Current+Location/"&J27,"Get Directions") -> #REF! | I27: =Sheet1!#REF! -> #REF! | J27: =Sheet1!#REF! -> #REF! | L27: Huerta
A28: =Sheet1!#REF! -> #REF! | B28: =Sheet1!#REF! -> #REF! | C28: =Sheet1!#REF! -> #REF! | D28: =Sheet1!#REF! -> #REF! | G28: =HYPERLINK("https://www.google.com/maps/dir/Current+Location/"&J28,"Get Directions") -> #REF! | I28: =Sheet1!#REF! -> #REF! | J28: =Sheet1!#REF! -> #REF! | L28: Ximenez
A29: =Sheet1!#REF! -> #REF! | B29: =Sheet1!#REF! -> #REF! | C29: =Sheet1!#REF! -> #REF! | D29: =Sheet1!#REF! -> #REF! | G29: =HYPERLINK("https://www.google.com/maps/dir/Current+Location/"&J29,"Get Directions") -> #REF! | I29: =Sheet1!#REF! -> #REF! | J29: =Sheet1!#REF! -> #REF!
A30: =Sheet1!#REF! -> #REF! | B30: =Sheet1!#REF! -> #REF! | C30: =Sheet1!#REF! -> #REF! | D30: =Sheet1!#REF! -> #REF! | G30: =HYPERLINK("https://www.google.com/maps/dir/Current+Location/"&J30,"Get Directions") -> #REF! | I30: =Sheet1!#REF! -> #REF! | J30: =Sheet1!#REF! -> #REF!
A31: =Sheet1!#REF! -> #REF! | B31: =Sheet1!#REF! -> #REF! | C31: =Sheet1!#REF! -> #REF! | D31: =Sheet1!#REF! -> #REF! | G31: =HYPERLINK("https://www.google.com/maps/dir/Current+Location/"&J31,"Get Directions") -> #REF! | I31: =Sheet1!#REF! -> #REF! | J31: =Sheet1!#REF! -> #REF!
A32: =Sheet1!#REF! -> #REF! | B32: =Sheet1!#REF! -> #REF! | C32: =Sheet1!#REF! -> #REF! | D32: =Sheet1!#REF! -> #REF! | G32: =HYPERLINK("https://www.google.com/maps/dir/Current+Location/"&J32,"Get Directions") -> #REF! | I32: =Sheet1!#REF! -> #REF! | J32: =Sheet1!#REF! -> #REF!
A33: =Sheet1!#REF! -> #REF! | B33: =Sheet1!#REF! -> #REF! | C33: =Sheet1!#REF! -> #REF! | D33: =Sheet1!#REF! -> #REF! | G33: =HYPERLINK("https://www.google.com/maps/dir/Current+Location/"&J33,"Get Directions") -> #REF! | I33: =Sheet1!#REF! -> #REF! | J33: =Sheet1!#REF! -> #REF!
A34: =Sheet1!#REF! -> #REF! | B34: =Sheet1!#REF! -> #REF! | C34: =Sheet1!#REF! -> #REF! | D34: =Sheet1!#REF! -> #REF! | G34: =HYPERLINK("https://www.google.com/maps/dir/Current+Location/"&J34,"Get Directions") -> #REF! | I34: =Sheet1!#REF! -> #REF! | J34: =Sheet1!#REF! -> #REF!
A35: =Sheet1!#REF! -> #REF! | B35: =Sheet1!#REF! -> #REF! | C35: =Sheet1!#REF! -> #REF! | D35: =Sheet1!#REF! -> #REF! | G35: =HYPERLINK("https://www.google.com/maps/dir/Current+Location/"&J35,"Get Directions") -> #REF! | I35: =Sheet1!#REF! -> #REF! | J35: =Sheet1!#REF! -> #REF!
A36: =Sheet1!#REF! -> #REF! | B36: =Sheet1!#REF! -> #REF! | D36: =Sheet1!#REF! -> #REF! | G36: =HYPERLINK("https://www.google.com/maps/dir/Current+Location/"&J36,"Get Directions") -> #REF! | I36: =Sheet1!#REF! -> #REF! | J36: =Sheet1!#REF! -> #REF!
A37: =Sheet1!#REF! -> #REF! | B37: =Sheet1!#REF! -> #REF! | D37: =Sheet1!#REF! -> #REF! | G37: =HYPERLINK("https://www.google.com/maps/dir/Current+Location/"&J37,"Get Directions") -> #REF! | I37: =Sheet1!#REF! -> #REF! | J37: =Sheet1!#REF! -> #REF!
A38: =Sheet1!#REF! -> #REF! | B38: =Sheet1!#REF! -> #REF! | D38: =Sheet1!#REF! -> #REF! | G38: =HYPERLINK("https://www.google.com/maps/dir/Current+Location/"&J38,"Get Directions") -> #REF! | I38: =Sheet1!#REF! -> #REF! | J38: =Sheet1!#REF! -> #REF!
A39: =Sheet1!#REF! -> #REF! | B39: =Sheet1!#REF! -> #REF! | D39: =Sheet1!#REF! -> #REF! | G39: =HYPERLINK("https://www.google.com/maps/dir/Current+Location/"&J39,"Get Directions") -> #REF! | I39: =Sheet1!#REF! -> #REF! | J39: =Sheet1!#REF! -> #REF!
A40: =Sheet1!#REF! -> #REF! | B40: =Sheet1!#REF! -> #REF! | D40: =Sheet1!#REF! -> #REF! | G40: =HYPERLINK("https://www.google.com/maps/dir/Current+Location/"&J40,"Get Directions") -> #REF! | I40: =Sheet1!#REF! -> #REF! | J40: =Sheet1!#REF! -> #REF!
...

Sheet Sheet3

Sheet Clients
A1: ClientID | B1: CauseNo | C1: WardFirst | D1: WardLast | E1: Status | F1: PrimaryEmail | G1: CCEmail | H1: ConsentToEmail | I1: DoNotEmailReason | J1: LastContacted | K1: NextFollowUp
B2: =Sheet1!#REF! -> #REF! | C2: =Sheet1!#REF! -> #REF! | D2: =Sheet1!#REF! -> #REF! | F2: =Sheet1!#REF! -> #REF! | G2: =IF(Sheet1!#REF!="","",Sheet1!#REF!) -> #REF! | H2: =IF(Table1[[#This Row],[PrimaryEmail]]<>"","Yes","") -> #REF!
B3: =Sheet1!#REF! -> #REF! | C3: =Sheet1!#REF! -> #REF! | D3: =Sheet1!#REF! -> #REF! | F3: =Sheet1!#REF! -> #REF! | G3: =IF(Sheet1!#REF!="","",Sheet1!#REF!) -> #REF! | H3: =IF(Table1[[#This Row],[PrimaryEmail]]<>"","Yes","") -> #REF!
B4: =Sheet1!#REF! -> #REF! | C4: =Sheet1!#REF! -> #REF! | D4: =Sheet1!#REF! -> #REF! | F4: =Sheet1!#REF! -> #REF! | G4: =IF(Sheet1!#REF!="","",Sheet1!#REF!) -> #REF! | H4: =IF(Table1[[#This Row],[PrimaryEmail]]<>"","Yes","") -> #REF!
B5: =Sheet1!#REF! -> #REF! | C5: =Sheet1!#REF! -> #REF! | D5: =Sheet1!#REF! -> #REF! | F5: =Sheet1!#REF! -> #REF! | G5: =IF(Sheet1!#REF!="","",Sheet1!#REF!) -> #REF! | H5: =IF(Table1[[#This Row],[PrimaryEmail]]<>"","Yes","") -> #REF!
B6: =Sheet1!#REF! -> #REF! | C6: =Sheet1!#REF! -> #REF! | D6: =Sheet1!#REF! -> #REF! | F6: =Sheet1!#REF! -> #REF! | G6: =IF(Sheet1!#REF!="","",Sheet1!#REF!) -> #REF! | H6: =IF(Table1[[#This Row],[PrimaryEmail]]<>"","Yes","") -> #REF!
B7: =Sheet1!#REF! -> #REF! | C7: =Sheet1!#REF! -> #REF! | D7: =Sheet1!#REF! -> #REF! | F7: =Sheet1!#REF! -> #REF! | G7: =IF(Sheet1!#REF!="","",Sheet1!#REF!) -> #REF! | H7: =IF(Table1[[#This Row],[PrimaryEmail]]<>"","Yes","") -> #REF!
B8: =Sheet1!#REF! -> #REF! | C8: =Sheet1!#REF! -> #REF! | D8: =Sheet1!#REF! -> #REF! | F8: =Sheet1!#REF! -> #REF! | G8: =IF(Sheet1!#REF!="","",Sheet1!#REF!) -> #REF! | H8: =IF(Table1[[#This Row],[PrimaryEmail]]<>"","Yes","") -> #REF!
B9: =Sheet1!#REF! -> #REF! | C9: =Sheet1!#REF! -> #REF! | D9: =Sheet1!#REF! -> #REF! | F9: =Sheet1!#REF! -> #REF! | G9: =IF(Sheet1!#REF!="","",Sheet1!#REF!) -> #REF! | H9: =IF(Table1[[#This Row],[PrimaryEmail]]<>"","Yes","") -> #REF!
B10: =Sheet1!#REF! -> #REF! | C10: =Sheet1!#REF! -> #REF! | D10: =Sheet1!#REF! -> #REF! | F10: =Sheet1!#REF! -> #REF! | G10: =IF(Sheet1!#REF!="","",Sheet1!#REF!) -> #REF! | H10: =IF(Table1[[#This Row],[PrimaryEmail]]<>"","Yes","") -> #REF!
B11: =Sheet1!#REF! -> #REF! | C11: =Sheet1!#REF! -> #REF! | D11: =Sheet1!#REF! -> #REF! | F11: =Sheet1!#REF! -> #REF! | G11: =IF(Sheet1!#REF!="","",Sheet1!#REF!) -> #REF! | H11: =IF(Table1[[#This Row],[PrimaryEmail]]<>"","Yes","") -> #REF!
B12: =Sheet1!#REF! -> #REF! | C12: =Sheet1!#REF! -> #REF! | D12: =Sheet1!#REF! -> #REF! | F12: =Sheet1!#REF! -> #REF! | G12: =IF(Sheet1!#REF!="","",Sheet1!#REF!) -> #REF! | H12: =IF(Table1[[#This Row],[PrimaryEmail]]<>"","Yes","") -> #REF!
B13: =Sheet1!#REF! -> #REF! | C13: =Sheet1!#REF! -> #REF! | D13: =Sheet1!#REF! -> #REF! | F13: =Sheet1!#REF! -> #REF! | G13: =IF(Sheet1!#REF!="","",Sheet1!#REF!) -> #REF! | H13: =IF(Table1[[#This Row],[PrimaryEmail]]<>"","Yes","") -> #REF!
... B33: =Sheet1!#REF! -> #REF! | C33: =Sheet1!#REF! -> #REF! | D33: =Sheet1!#REF! -> #REF! | F33: =Sheet1!#REF! -> #REF! | G33: =IF(Sheet1!#REF!="","",Sheet1!#REF!) -> #REF! | H33: =IF(Table1[[#This Row],[PrimaryEmail]]<>"","Yes","") -> #REF!
B34: =Sheet1!#REF! -> #REF! | C34: =Sheet1!#REF! -> #REF! | D34: =Sheet1!#REF! -> #REF! | E34: A | F34: =Sheet1!#REF! -> #REF! | G34: =IF(Sheet1!#REF!="","",Sheet1!#REF!) -> #REF! | H34: =IF(Table1[[#This Row],[PrimaryEmail]]<>"","Yes","") -> #REF!
B35: =Sheet1!#REF! -> #REF! | C35: =Sheet1!#REF! -> #REF! | D35: =Sheet1!#REF! -> #REF! | E35: A | F35: =Sheet1!#REF! -> #REF! | G35: =IF(Sheet1!#REF!="","",Sheet1!#REF!) -> #REF! | H35: =IF(Table1[[#This Row],[PrimaryEmail]]<>"","Yes","") -> #REF!
B36: =Sheet1!#REF! -> #REF! | C36: =Sheet1!#REF! -> #REF! | D36: =Sheet1!#REF! -> #REF! | E36: A | F36: =Sheet1!#REF! -> #REF! | G36: =IF(Sheet1!#REF!="","",Sheet1!#REF!) -> #REF! | H36: =IF(Table1[[#This Row],[PrimaryEmail]]<>"","Yes","") -> #REF!
B37: =Sheet1!#REF! -> #REF! | C37: =Sheet1!#REF! -> #REF! | D37: =Sheet1!#REF! -> #REF! | E37: A | F37: =Sheet1!#REF! -> #REF! | G37: =IF(Sheet1!#REF!="","",Sheet1!#REF!) -> #REF! | H37: =IF(Table1[[#This Row],[PrimaryEmail]]<>"","Yes","") -> #REF!
B38: =Sheet1!#REF! -> #REF! | C38: =Sheet1!#REF! -> #REF! | D38: =Sheet1!#REF! -> #REF! | E38: A | F38: =Sheet1!#REF! -> #REF! | G38: =IF(Sheet1!#REF!="","",Sheet1!#REF!) -> #REF! | H38: =IF(Table1[[#This Row],[PrimaryEmail]]<>"","Yes","") -> #REF!
B39: =Sheet1!#REF! -> #REF! | C39: =Sheet1!#REF! -> #REF! | D39: =Sheet1!#REF! -> #REF! | E39: A | F39: =Sheet1!#REF! -> #REF! | G39: =IF(Sheet1!#REF!="","",Sheet1!#REF!) -> #REF! | H39: =IF(Table1[[#This Row],[PrimaryEmail]]<>"","Yes","") -> #REF!
B40: =Sheet1!#REF! -> #REF! | C40: =Sheet1!#REF! -> #REF! | D40: =Sheet1!#REF! -> #REF! | E40: A | F40: =Sheet1!#REF! -> #REF! | G40: =IF(Sheet1!#REF!="","",Sheet1!#REF!) -> #REF! | H40: =IF(Table1[[#This Row],[PrimaryEmail]]<>"","Yes","") -> #REF!
B41: =Sheet1!#REF! -> #REF! | C41: =Sheet1!#REF! -> #REF! | D41: =Sheet1!#REF! -> #REF! | E41: A | F41: =Sheet1!#REF! -> #REF! | G41: =IF(Sheet1!#REF!="","",Sheet1!#REF!) -> #REF! | H41: =IF(Table1[[#This Row],[PrimaryEmail]]<>"","Yes","") -> #REF!
B42: =Sheet1!#REF! -> #REF! | C42: =Sheet1!#REF! -> #REF! | D42: =Sheet1!#REF! -> #REF! | E42: A | F42: =Sheet1!#REF! -> #REF! | G42: =IF(Sheet1!#REF!="","",Sheet1!#REF!) -> #REF! | H42: =IF(Table1[[#This Row],[PrimaryEmail]]<>"","Yes","") -> #REF!
B43: =Sheet1!#REF! -> #REF! | C43: =Sheet1!#REF! -> #REF! | D43: =Sheet1!#REF! -> #REF! | E43: A | F43: =Sheet1!#REF! -> #REF! | G43: =IF(Sheet1!#REF!="","",Sheet1!#REF!) -> #REF! | H43: =IF(Table1[[#This Row],[PrimaryEmail]]<>"","Yes","") -> #REF!
B44: =Sheet1!#REF! -> #REF! | C44: =Sheet1!#REF! -> #REF! | D44: =Sheet1!#REF! -> #REF! | E44: A | F44: =Sheet1!#REF! -> #REF! | G44: =IF(Sheet1!#REF!="","",Sheet1!#REF!) -> #REF! | H44: =IF(Table1[[#This Row],[PrimaryEmail]]<>"","Yes","") -> #REF!
B45: =Sheet1!#REF! -> #REF! | C45: =Sheet1!#REF! -> #REF! | D45: =Sheet1!#REF! -> #REF! | E45: A | F45: =Sheet1!#REF! -> #REF! | G45: =IF(Sheet1!#REF!="","",Sheet1!#REF!) -> #REF! | H45: =IF(Table1[[#This Row],[PrimaryEmail]]<>"","Yes","") -> #REF!
... B827: =Sheet1!#REF! -> #REF! | C827: =Sheet1!#REF! -> #REF! | D827: =Sheet1!#REF! -> #REF! | E827: A | F827: =Sheet1!#REF! -> #REF! | G827: =IF(Sheet1!#REF!="","",Sheet1!#REF!) -> #REF! | H827: =IF(Table1[[#This Row],[PrimaryEmail]]<>"","Yes","") -> #REF!
B828: =Sheet1!D2 -> 05-082942 | C828: =Sheet1!B2 -> Oscar | D828: =Sheet1!A2 -> Luna | E828: A | F828: =Sheet1!M2 -> Medelc64@gmail.com | G828: =IF(Sheet1!S2="","",Sheet1!S2) | H828: =IF(Table1[[#This Row],[PrimaryEmail]]<>"","Yes","") -> Yes
B829: =Sheet1!D3 -> 06-085777 | C829: =Sheet1!B3 -> Cos | D829: =Sheet1!A3 -> Cas | E829: A | F829: =Sheet1!M3 -> lazarbre@hotmail.com | G829: =IF(Sheet1!S3="","",Sheet1!S3) | H829: =IF(Table1[[#This Row],[PrimaryEmail]]<>"","Yes","") -> Yes
B830: =Sheet1!D4 -> 09-001594 | C830: =Sheet1!B4 -> Jayleen | D830: =Sheet1!A4 -> Jaimes | E830: A | F830: =Sheet1!M4 -> cjohnson@familyeldercare.org_ | G830: =IF(Sheet1!S4="","",Sheet1!S4) | H830: =IF(Table1[[#This Row],[PrimaryEmail]]<>"","Yes","") -> Yes
B831: =Sheet1!D5 -> 14-000172 | C831: =Sheet1!B5 -> Quinn | D831: =Sheet1!A5 -> Reich | E831: A | F831: =Sheet1!M5 -> leboeuf0807@gmail.com | G831: =IF(Sheet1!S5="","",Sheet1!S5) | H831: =IF(Table1[[#This Row],[PrimaryEmail]]<>"","Yes","") -> Yes
B832: =Sheet1!D6 -> 15-000428 | C832: =Sheet1!B6 -> Ty | D832: =Sheet1!A6 -> Cox | E832: A | F832: =Sheet1!M6 -> amykcox1944@gmail.com | G832: =IF(Sheet1!S6="","",Sheet1!S6) | H832: =IF(Table1[[#This Row],[PrimaryEmail]]<>"","Yes","") -> Yes
B833: =Sheet1!D7 -> 17-000201 | C833: =Sheet1!B7 -> Jay | D833: =Sheet1!A7 -> Roberts | E833: A | F833: =Sheet1!M7 -> strebornelle@gmail.com | G833: =IF(Sheet1!S7="","",Sheet1!S7) | H833: =IF(Table1[[#This Row],[PrimaryEmail]]<>"","Yes","") -> Yes
B834: =Sheet1!D8 -> 18-000194 | C834: =Sheet1!B8 -> A | D834: =Sheet1!A8 -> Toney | E834: A | F834: =Sheet1!M8 -> 0 | G834: =IF(Sheet1!S8="","",Sheet1!S8) | H834: =IF(Table1[[#This Row],[PrimaryEmail]]<>"","Yes","") -> Yes
B835: =Sheet1!D9 -> 19-002069 | C835: =Sheet1!B9 -> Gabriela | D835: =Sheet1!A9 -> Huerta | E835: A | F835: =Sheet1!M9 -> 0 | G835: =IF(Sheet1!S9="","",Sheet1!S9) | H835: =IF(Table1[[#This Row],[PrimaryEmail]]<>"","Yes","") -> Yes
B836: =Sheet1!D10 -> 99-071988 | C836: =Sheet1!B10 -> Dyana | D836: =Sheet1!A10 -> Limon-mercado | E836: A | F836: =Sheet1!M10 -> rlontkowski@familyeldercare.org | G836: =IF(Sheet1!S10="","",Sheet1!S10) | H836: =IF(Table1[[#This Row],[PrimaryEmail]]<>"","Yes","") -> Yes
B837: =Sheet1!D11 -> 0 | C837: =Sheet1!B11 -> 0 | D837: =Sheet1!A11 -> 0 | E837: A | F837: =Sheet1!M11 -> 0 | G837: =IF(Sheet1!S11="","",Sheet1!S11) | H837: =IF(Table1[[#This Row],[PrimaryEmail]]<>"","Yes","") -> Yes
B838: =Sheet1!D12 -> 0 | C838: =Sheet1!B12 -> 0 | D838: =Sheet1!A12 -> 0 | E838: A | F838: =Sheet1!M12 -> 0 | G838: =IF(Sheet1!S12="","",Sheet1!S12) | H838: =IF(Table1[[#This Row],[PrimaryEmail]]<>"","Yes","") -> Yes
B839: =Sheet1!D13 -> 0 | C839: =Sheet1!B13 -> 0 | D839: =Sheet1!A13 -> 0 | E839: A | F839: =Sheet1!M13 -> 0 | G839: =IF(Sheet1!S13="","",Sheet1!S13) | H839: =IF(Table1[[#This Row],[PrimaryEmail]]<>"","Yes","") -> Yes
... B1000: =Sheet1!D174 -> 0 | C1000: =Sheet1!B174 -> 0 | D1000: =Sheet1!A174 -> 0 | E1000: A | F1000: =Sheet1!M174 -> 0 | G1000: =IF(Sheet1!S174="","",Sheet1!S174) | H1000: =IF(Table1[[#This Row],[PrimaryEmail]]<>"","Yes","") -> Yes

Sheet Contacts
A1: ContactID | B1: DisplayName | C1: EmailPrimary | D1: EmailAlt | E1: Phone | F1: Org | G1: RoleType | H1: ConsentToEmail | I1: Notes

Sheet ClientContacts
A1: ClientID | B1: ContactID | C1: Relationship | D1: IsPrimary

Sheet Messages
A1: LogID | B1: ClientID | C1: CauseNo | D1: Timestamp | E1: Provider | F1: GmailMessageId | G1: GmailThreadId | H1: ThreadURL | I1: From | J1: To | K1: CC | L1: Subject | M1: Snippet | N1: BodyPreview | O1: HasAttachments | P1: TemplateID | Q1: TemplateVersion | R1: Module | S1: Direction | T1: Status | U1: ErrorNote
A2: e168efc0-d51b-4b07-9306-a8c320cf0bc2 | C2: 21-001411 | D2: 2025-10-15T09:24:24 | E2: gmail | I2: yourname@gmail.com | J2: txgirl14boys@gmail.com | L2: Friendly Reminder | M2: Hello there, This is a friendly reminder about your upcoming item for John Carter Wagner (Cause #21-001411). If you have questions, reply to this email. Thank you, Cour | O2: N | P2: simple_reminder | Q2: 1.0.0 | R2: Email | S2: OUTBOUND | T2: PREVIEW
A3: 6e3370df-22dc-4647-ba8a-4870cd35104c | C3: 17-000729 | D3: 2025-10-15T09:24:28 | E3: gmail | I3: yourname@gmail.com | J3: ljdenis214@gmail.com | L3: Friendly Reminder | M3: Hello there, This is a friendly reminder about your upcoming item for Abigail Dennis (Cause #17-000729). If you have questions, reply to this email. Thank you, Court Vis | O3: N | P3: simple_reminder | Q3: 1.0.0 | R3: Email | S3: OUTBOUND | T3: PREVIEW
A4: 5e9d9125-a05e-4183-addc-8c286c60eab4 | C4: 22-001301 | D4: 2025-10-15T09:24:34 | E4: gmail | I4: yourname@gmail.com | J4: amyhalford710@gmail.com | L4: Friendly Reminder | M4: Hello there, This is a friendly reminder about your upcoming item for Jon Tyler Halford (Cause #22-001301). If you have questions, reply to this email. Thank you, Court | O4: N | P4: simple_reminder | Q4: 1.0.0 | R4: Email | S4: OUTBOUND | T4: PREVIEW
A5: 1a1bc251-4c10-4efc-a649-93deda2ad6a9 | C5: 22-002249 | D5: 2025-10-15T09:24:40 | E5: gmail | I5: yourname@gmail.com | J5: lina@mircareconsultants.com | L5: Friendly Reminder | M5: Hello there, This is a friendly reminder about your upcoming item for Daniel Braden (Cause #22-002249). If you have questions, reply to this email. Thank you, Court Vis | O5: N | P5: simple_reminder | Q5: 1.0.0 | R5: Email | S5: OUTBOUND | T5: PREVIEW
A6: 7546fba4-de1b-4037-a1a4-3eeef1bd00cc | C6: 16-000206 | D6: 2025-10-15T09:24:46 | E6: gmail | I6: yourname@gmail.com | J6: valmayerik@gmail.com | L6: Friendly Reminder | M6: Hello there, This is a friendly reminder about your upcoming item for Julian Mayerik Conner (Cause #16-000206). If you have questions, reply to this email. Thank you, C | O6: N | P6: simple_reminder | Q6: 1.0.0 | R6: Email | S6: OUTBOUND | T6: PREVIEW
A7: d868a9c7-ae38-46fc-bc9d-1201607715aa | C7: 14-002049 | D7: 2025-10-15T09:24:51 | E7: gmail | I7: yourname@gmail.com | J7: kedejong@msn.com | L7: Friendly Reminder | M7: Hello there, This is a friendly reminder about your upcoming item for Brendan James De Jong (Cause #14-002049). If you have questions, reply to this email. Thank you, Co | O7: N | P7: simple_reminder | Q7: 1.0.0 | R7: Email | S7: OUTBOUND | T7: PREVIEW
A8: 10b3e290-0e95-4771-930f-b475121db552 | C8: 06-084450 | D8: 2025-10-15T09:25:06 | E8: gmail | I8: yourname@gmail.com | J8: braden ca | L8: Friendly Reminder | M8: Hello there, This is a friendly reminder about your upcoming item for Kimberly Grace Eudy (Cause #06-084450). If you have questions, reply to this email. Thank you, Cour | O8: N | P8: simple_reminder | Q8: 1.0.0 | R8: Email | S8: OUTBOUND | T8: PREVIEW
A9: bc1e6de9-72b7-4caa-ae38-e0ab6afb3494 | C9: 20-001710 | D9: 2025-10-15T09:25:12 | E9: gmail | I9: yourname@gmail.com | J9: apjon1@yahoo.com | L9: Friendly Reminder | M9: Hello there, This is a friendly reminder about your upcoming item for Andrew Colton Jones (Cause #20-001710). If you have questions, reply to this email. Thank you, Cour | O9: N | P9: simple_reminder | Q9: 1.0.0 | R9: Email | S9: OUTBOUND | T9: PREVIEW
A10: ce1cbe32-4b32-4894-8541-d725acc65dc7 | C10: 18-001798 | D10: 2025-10-15T09:25:16 | E10: gmail | I10: yourname@gmail.com | J10: randalpark@yahoo.com | L10: Friendly Reminder | M10: Hello there, This is a friendly reminder about your upcoming item for Mina Park (Cause #18-001798). If you have questions, reply to this email. Thank you, Court Visitor | O10: N | P10: simple_reminder | Q10: 1.0.0 | R10: Email | S10: OUTBOUND | T10: PREVIEW
A11: 5d8eca48-09ac-4ca3-83eb-b39e717ef312 | C11: 19-000060 | D11: 2025-10-15T09:25:22 | E11: gmail | I11: yourname@gmail.com | J11: courtneythomasou91@gmail.com | L11: Friendly Reminder | M11: Hello there, This is a friendly reminder about your upcoming item for Luke Thomas Bennett (Cause #19-000060). If you have questions, reply to this email. Thank you, Cou | O11: N | P11: simple_reminder | Q11: 1.0.0 | R11: Email | S11: OUTBOUND | T11: PREVIEW
A12: 7da1b910-478d-432c-9286-91706a478c08 | C12: 15-002046 | D12: 2025-10-15T09:25:29 | E12: gmail | I12: yourname@gmail.com | J12: mdavidson7@austin.rr.com | L12: Friendly Reminder | M12: Hello there, This is a friendly reminder about your upcoming item for Anthony Michael Davidson (Cause #15-002046). If you have questions, reply to this email. Thank you, | O12: N | P12: simple_reminder | Q12: 1.0.0 | R12: Email | S12: OUTBOUND | T12: PREVIEW
A13: 7ffcf17c-f99c-4071-9f5f-673a0d1db596 | C13: 12-000189 | D13: 2025-10-15T09:25:34 | E13: gmail | I13: yourname@gmail.com | J13: lismooring@aol.com | K13: danieldavidson879@gmail.com | L13: Friendly Reminder | M13: Hello there, This is a friendly reminder about your upcoming item for Michael Todd Dodson (Cause #12-000189). If you have questions, reply to this email. Thank you, Cour | O13: N | P13: simple_reminder | Q13: 1.0.0 | R13: Email | S13: OUTBOUND | T13: PREVIEW
A14: 8a690335-fc9d-4876-89cf-dc403d9d4939 | C14: 24-001242 | D14: 2025-10-15T09:25:41 | E14: gmail | I14: yourname@gmail.com | J14: meenu.jain@gmail.com | K14: ankur.ankurjain@gmail.com | L14: Friendly Reminder | M14: Hello there, This is a friendly reminder about your upcoming item for Ryan Jain (Cause #24-001242). If you have questions, reply to this email. Thank you, Court Visitor | O14: N | P14: simple_reminder | Q14: 1.0.0 | R14: Email | S14: OUTBOUND | T14: PREVIEW
A15: 0bc61be1-a139-4817-9955-8bfcdc36bf4c | C15: 09-000016 | D15: 2025-10-15T09:25:48 | E15: gmail | I15: yourname@gmail.com | J15: melyssaloy@mac.com | L15: Friendly Reminder | M15: Hello there, This is a friendly reminder about your upcoming item for Mary K. Loy (Cause #09-000016). If you have questions, reply to this email. Thank you, Court Visito | O15: N | P15: simple_reminder | Q15: 1.0.0 | R15: Email | S15: OUTBOUND | T15: PREVIEW
A16: fb5a4f08-2610-4668-a8b5-f644d18b74a2 | C16: 05-82942 | D16: 2025-10-15T09:25:55 | E16: gmail | I16: yourname@gmail.com | J16: medelc64@gmail.com | L16: Friendly Reminder | M16: Hello there, This is a friendly reminder about your upcoming item for Oscar Luna (Cause #05-82942). If you have questions, reply to this email. Thank you, Court Visitor | O16: N | P16: simple_reminder | Q16: 1.0.0 | R16: Email | S16: OUTBOUND | T16: PREVIEW
A17: 9ade24ab-75f3-414b-a92d-9f05813813fd | C17: 06-085777 | D17: 2025-10-15T09:26:04 | E17: gmail | I17: yourname@gmail.com | J17: brefaye@hotmail.com | K17: lazarbre@hotmail.com | L17: Friendly Reminder | M17: Hello there, This is a friendly reminder about your upcoming item for Benjamin Brener (Cause #06-085777). If you have questions, reply to this email. Thank you, Court Vi | O17: N | P17: simple_reminder | Q17: 1.0.0 | R17: Email | S17: OUTBOUND | T17: PREVIEW
A18: 607cdc2b-6895-43d6-bbc1-c05da6e095b6 | C18: 09-001594 | D18: 2025-10-15T09:26:07 | E18: gmail | I18: yourname@gmail.com | J18: cjohnson@familyeldercare.org | L18: Friendly Reminder | M18: Hello there, This is a friendly reminder about your upcoming item for Mark Potter (Cause #09-001594). If you have questions, reply to this email. Thank you, Court Visito | O18: N | P18: simple_reminder | Q18: 1.0.0 | R18: Email | S18: OUTBOUND | T18: PREVIEW
A19: b8fa8ed3-880a-41de-8b70-5fc75d589834 | C19: 14-000172 | D19: 2025-10-15T09:26:15 | E19: gmail | I19: yourname@gmail.com | J19: lleboeuf0807@gmail.com | L19: Friendly Reminder | M19: Hello there, This is a friendly reminder about your upcoming item for Quinn Reich (Cause #14-000172). If you have questions, reply to this email. Thank you, Court Visito | O19: N | P19: simple_reminder | Q19: 1.0.0 | R19: Email | S19: OUTBOUND | T19: PREVIEW
A20: 8fdfc5e3-c41d-4a80-a729-d1f74ab4b0bd | C20: 15-000428 | D20: 2025-10-15T09:26:20 | E20: gmail | I20: yourname@gmail.com | J20: mattjoncox@gmail.com | K20: amykcox1964@gmail.com | L20: Friendly Reminder | M20: Hello there, This is a friendly reminder about your upcoming item for Ty Cox (Cause #15-000428). If you have questions, reply to this email. Thank you, Court Visitor | O20: N | P20: simple_reminder | Q20: 1.0.0 | R20: Email | S20: OUTBOUND | T20: PREVIEW
A21: 723b18a7-5cd5-4137-92e3-fffd6b0d1434 | C21: 17-000201 | D21: 2025-10-15T09:26:26 | E21: gmail | I21: yourname@gmail.com | J21: streboryaj@gmail.com | K21: strebornelle@gmail.com | L21: Friendly Reminder | M21: Hello there, This is a friendly reminder about your upcoming item for Jay Roberts (Cause #17-000201). If you have questions, reply to this email. Thank you, Court Visito | O21: N | P21: simple_reminder | Q21: 1.0.0 | R21: Email | S21: OUTBOUND | T21: PREVIEW
A22: 6e8d200f-2cc1-4d27-ad0d-a6c2f511b114 | C22: 18-000194 | D22: 2025-10-15T09:26:34 | E22: gmail | I22: yourname@gmail.com | J22: datoney2@gmail.com | L22: Friendly Reminder | M22: Hello there, This is a friendly reminder about your upcoming item for Emma Toney (Cause #18-000194). If you have questions, reply to this email. Thank you, Court Visitor | O22: N | P22: simple_reminder | Q22: 1.0.0 | R22: Email | S22: OUTBOUND | T22: PREVIEW
A23: 84e26700-6fee-4093-941b-8473282f398b | C23: 99-071988 | D23: 2025-10-15T09:26:40 | E23: gmail | I23: yourname@gmail.com | J23: rlontkowski@familyeldercare.org | L23: Friendly Reminder | M23: Hello there, This is a friendly reminder about your upcoming item for Jose Ximenez (Cause #99-071988). If you have questions, reply to this email. Thank you, Court Visit | O23: N | P23: simple_reminder | Q23: 1.0.0 | R23: Email | S23: OUTBOUND | T23: PREVIEW
A24: 5ac79097-2d31-40ce-ae24-562545d383d4 | C24: 05-082943 | D24: 2025-10-15T09:26:46 | E24: gmail | I24: yourname@gmail.com | J24: magda.wolk@gmail.com | L24: Friendly Reminder | M24: Hello there, This is a friendly reminder about your upcoming item for James Wolk (Cause #05-082943). If you have questions, reply to this email. Thank you, Court Visitor | O24: N | P24: simple_reminder | Q24: 1.0.0 | R24: Email | S24: OUTBOUND | T24: PREVIEW
A25: 0f795184-b261-4873-860f-b5644d99b2a3 | C25: 13-000934 | D25: 2025-10-15T09:26:53 | E25: gmail | I25: yourname@gmail.com | J25: wendyjimmerson@gmail.com | L25: Friendly Reminder | M25: Hello there, This is a friendly reminder about your upcoming item for Abby Jimmerson (Cause #13-000934). If you have questions, reply to this email. Thank you, Court Vis | O25: N | P25: simple_reminder | Q25: 1.0.0 | R25: Email | S25: OUTBOUND | T25: PREVIEW
A26: 117715dc-aa87-46d2-a3f0-3a9d71e025b3 | C26: 19-000694 | D26: 2025-10-15T09:26:58 | E26: gmail | I26: yourname@gmail.com | J26: tpcaglejr@gmail.com | K26: none | L26: Friendly Reminder | M26: Hello there, This is a friendly reminder about your upcoming item for Sara Cagle (Cause #19-000694). If you have questions, reply to this email. Thank you, Court Visitor | O26: N | P26: simple_reminder | Q26: 1.0.0 | R26: Email | S26: OUTBOUND | T26: PREVIEW
A27: 67389d53-3c85-4778-a883-c538872f318b | C27: 21-000066 | D27: 2025-10-15T09:27:04 | E27: gmail | I27: yourname@gmail.com | J27: JeM0801@gmail.com | K27: none | L27: Friendly Reminder | M27: Hello there, This is a friendly reminder about your upcoming item for Mason Mogonye (Cause #21-000066). If you have questions, reply to this email. Thank you, Court Visi | O27: N | P27: simple_reminder | Q27: 1.0.0 | R27: Email | S27: OUTBOUND | T27: PREVIEW
A28: cc779035-bdc4-469a-89a5-cff2b2404f48 | C28: 22-002744 | D28: 2025-10-15T09:27:18 | E28: gmail | I28: yourname@gmail.com | J28: thezarolas@gmail.com | K28: none | L28: Friendly Reminder | M28: Hello there, This is a friendly reminder about your upcoming item for Aidan Zarola (Cause #22-002744). If you have questions, reply to this email. Thank you, Court Visit | O28: N | P28: simple_reminder | Q28: 1.0.0 | R28: Email | S28: OUTBOUND | T28: PREVIEW
A29: b5b01524-6466-43d2-bc30-a0588909d924 | C29: 22-195700 | D29: 2025-10-15T09:27:31 | E29: gmail | I29: yourname@gmail.com | J29: mayehres@gmail.com | L29: Friendly Reminder | M29: Hello there, This is a friendly reminder about your upcoming item for susan ehresman (Cause #22-195700). If you have questions, reply to this email. Thank you, Court Vis | O29: N | P29: simple_reminder | Q29: 1.0.0 | R29: Email | S29: OUTBOUND | T29: PREVIEW

Sheet MessageRecipients
A1: LogID | B1: ContactID | C1: Type
A2: e168efc0-d51b-4b07-9306-a8c320cf0bc2 | C2: TO
A3: 6e3370df-22dc-4647-ba8a-4870cd35104c | C3: TO
A4: 5e9d9125-a05e-4183-addc-8c286c60eab4 | C4: TO
A5: 1a1bc251-4c10-4efc-a649-93deda2ad6a9 | C5: TO
A6: 7546fba4-de1b-4037-a1a4-3eeef1bd00cc | C6: TO
A7: d868a9c7-ae38-46fc-bc9d-1201607715aa | C7: TO
A8: 10b3e290-0e95-4771-930f-b475121db552 | C8: TO
A9: bc1e6de9-72b7-4caa-ae38-e0ab6afb3494 | C9: TO
A10: ce1cbe32-4b32-4894-8541-d725acc65dc7 | C10: TO
A11: 5d8eca48-09ac-4ca3-83eb-b39e717ef312 | C11: TO
A12: 7da1b910-478d-432c-9286-91706a478c08 | C12: TO
A13: 7ffcf17c-f99c-4071-9f5f-673a0d1db596 | C13: TO
... A37: b5b01524-6466-43d2-bc30-a0588909d924 | C37: TO

Sheet MessageLinks
A1: LogID | B1: ClientID
A2: e168efc0-d51b-4b07-9306-a8c320cf0bc2
A3: 6e3370df-22dc-4647-ba8a-4870cd35104c
A4: 5e9d9125-a05e-4183-addc-8c286c60eab4
A5: 1a1bc251-4c10-4efc-a649-93deda2ad6a9
A6: 7546fba4-de1b-4037-a1a4-3eeef1bd00cc
A7: d868a9c7-ae38-46fc-bc9d-1201607715aa
A8: 10b3e290-0e95-4771-930f-b475121db552
A9: bc1e6de9-72b7-4caa-ae38-e0ab6afb3494
A10: ce1cbe32-4b32-4894-8541-d725acc65dc7
A11: 5d8eca48-09ac-4ca3-83eb-b39e717ef312
A12: 7da1b910-478d-432c-9286-91706a478c08
A13: 7ffcf17c-f99c-4071-9f5f-673a0d1db596
... A29: b5b01524-6466-43d2-bc30-a0588909d924

Sheet TemplatesIndex
A1: TemplateID | B1: Version | C1: Purpose | D1: SubjectDefault | E1: FilePath
A2: simple_reminder | B2: 1.0.0 | C2: General gentle reminder | D2: Friendly Reminder | E2: C:\GoogleSync\Guardianship Files\data files\Emails\templates\simple_reminder.html
